[2023-02-13T21:44:09.724+0530] {taskinstance.py:1087} INFO - Dependencies all met for <TaskInstance: FX__Turnover.extract scheduled__2023-02-03T00:00:00+00:00 [queued]>
[2023-02-13T21:44:09.736+0530] {taskinstance.py:1087} INFO - Dependencies all met for <TaskInstance: FX__Turnover.extract scheduled__2023-02-03T00:00:00+00:00 [queued]>
[2023-02-13T21:44:09.737+0530] {taskinstance.py:1283} INFO - 
--------------------------------------------------------------------------------
[2023-02-13T21:44:09.737+0530] {taskinstance.py:1284} INFO - Starting attempt 3 of 4
[2023-02-13T21:44:09.737+0530] {taskinstance.py:1285} INFO - 
--------------------------------------------------------------------------------
[2023-02-13T21:44:09.753+0530] {taskinstance.py:1304} INFO - Executing <Task(PythonOperator): extract> on 2023-02-03 00:00:00+00:00
[2023-02-13T21:44:09.758+0530] {standard_task_runner.py:55} INFO - Started process 1402 to run task
[2023-02-13T21:44:09.762+0530] {standard_task_runner.py:82} INFO - Running: ['airflow', 'tasks', 'run', 'FX__Turnover', 'extract', 'scheduled__2023-02-03T00:00:00+00:00', '--job-id', '4004', '--raw', '--subdir', 'DAGS_FOLDER/FX_turnover.py', '--cfg-path', '/tmp/tmpys_8b9gk']
[2023-02-13T21:44:09.763+0530] {standard_task_runner.py:83} INFO - Job 4004: Subtask extract
[2023-02-13T21:44:09.822+0530] {task_command.py:389} INFO - Running <TaskInstance: FX__Turnover.extract scheduled__2023-02-03T00:00:00+00:00 [running]> on host DESKTOP-SQIOQPD.
[2023-02-13T21:44:09.888+0530] {taskinstance.py:1511} INFO - Exporting the following env vars:
AIRFLOW_CTX_DAG_EMAIL=nikheleshbhattacharyya@gmail.com
AIRFLOW_CTX_DAG_OWNER=airflow
AIRFLOW_CTX_DAG_ID=FX__Turnover
AIRFLOW_CTX_TASK_ID=extract
AIRFLOW_CTX_EXECUTION_DATE=2023-02-03T00:00:00+00:00
AIRFLOW_CTX_TRY_NUMBER=3
AIRFLOW_CTX_DAG_RUN_ID=scheduled__2023-02-03T00:00:00+00:00
[2023-02-13T21:44:15.041+0530] {taskinstance.py:1772} ERROR - Task failed with exception
Traceback (most recent call last):
  File "/usr/local/lib/python3.8/dist-packages/airflow/operators/python.py", line 175, in execute
    return_value = self.execute_callable()
  File "/usr/local/lib/python3.8/dist-packages/airflow/operators/python.py", line 192, in execute_callable
    return self.python_callable(*self.op_args, **self.op_kwargs)
  File "/root/airflow/dags/FX_turnover.py", line 139, in extract_fxturn
    driver.get(url)
  File "/usr/local/lib/python3.8/dist-packages/selenium/webdriver/remote/webdriver.py", line 449, in get
    self.execute(Command.GET, {"url": url})
  File "/usr/local/lib/python3.8/dist-packages/selenium/webdriver/remote/webdriver.py", line 440, in execute
    self.error_handler.check_response(response)
  File "/usr/local/lib/python3.8/dist-packages/selenium/webdriver/remote/errorhandler.py", line 245, in check_response
    raise exception_class(message, screen, stacktrace)
selenium.common.exceptions.WebDriverException: Message: unknown error: net::ERR_CONNECTION_RESET
  (Session info: headless chrome=109.0.5414.119)
Stacktrace:
#0 0x5559c56192a3 <unknown>
#1 0x5559c53d7f77 <unknown>
#2 0x5559c53cfe35 <unknown>
#3 0x5559c53c2f27 <unknown>
#4 0x5559c53c42d9 <unknown>
#5 0x5559c53c329e <unknown>
#6 0x5559c53c23d2 <unknown>
#7 0x5559c53c2225 <unknown>
#8 0x5559c53c0dc6 <unknown>
#9 0x5559c53c1244 <unknown>
#10 0x5559c53d9e88 <unknown>
#11 0x5559c544cb05 <unknown>
#12 0x5559c5434b32 <unknown>
#13 0x5559c544c47c <unknown>
#14 0x5559c5434903 <unknown>
#15 0x5559c5407ece <unknown>
#16 0x5559c5408fde <unknown>
#17 0x5559c566963e <unknown>
#18 0x5559c566cb79 <unknown>
#19 0x5559c564f89e <unknown>
#20 0x5559c566da83 <unknown>
#21 0x5559c5642505 <unknown>
#22 0x5559c568eca8 <unknown>
#23 0x5559c568ee36 <unknown>
#24 0x5559c56aa333 <unknown>
#25 0x7f52b6425609 start_thread

[2023-02-13T21:44:15.067+0530] {taskinstance.py:1322} INFO - Marking task as UP_FOR_RETRY. dag_id=FX__Turnover, task_id=extract, execution_date=20230203T000000, start_date=20230213T161409, end_date=20230213T161415
[2023-02-13T21:44:15.093+0530] {standard_task_runner.py:100} ERROR - Failed to execute job 4004 for task extract (Message: unknown error: net::ERR_CONNECTION_RESET
  (Session info: headless chrome=109.0.5414.119)
Stacktrace:
#0 0x5559c56192a3 <unknown>
#1 0x5559c53d7f77 <unknown>
#2 0x5559c53cfe35 <unknown>
#3 0x5559c53c2f27 <unknown>
#4 0x5559c53c42d9 <unknown>
#5 0x5559c53c329e <unknown>
#6 0x5559c53c23d2 <unknown>
#7 0x5559c53c2225 <unknown>
#8 0x5559c53c0dc6 <unknown>
#9 0x5559c53c1244 <unknown>
#10 0x5559c53d9e88 <unknown>
#11 0x5559c544cb05 <unknown>
#12 0x5559c5434b32 <unknown>
#13 0x5559c544c47c <unknown>
#14 0x5559c5434903 <unknown>
#15 0x5559c5407ece <unknown>
#16 0x5559c5408fde <unknown>
#17 0x5559c566963e <unknown>
#18 0x5559c566cb79 <unknown>
#19 0x5559c564f89e <unknown>
#20 0x5559c566da83 <unknown>
#21 0x5559c5642505 <unknown>
#22 0x5559c568eca8 <unknown>
#23 0x5559c568ee36 <unknown>
#24 0x5559c56aa333 <unknown>
#25 0x7f52b6425609 start_thread
; 1402)
[2023-02-13T21:44:15.138+0530] {local_task_job.py:159} INFO - Task exited with return code 1
[2023-02-13T21:44:15.178+0530] {taskinstance.py:2582} INFO - 0 downstream tasks scheduled from follow-on schedule check
