[2023-01-06T11:23:31.474+0530] {taskinstance.py:1087} INFO - Dependencies all met for <TaskInstance: Monthly.load scheduled__2023-01-05T00:00:00+00:00 [queued]>
[2023-01-06T11:23:31.501+0530] {taskinstance.py:1087} INFO - Dependencies all met for <TaskInstance: Monthly.load scheduled__2023-01-05T00:00:00+00:00 [queued]>
[2023-01-06T11:23:31.502+0530] {taskinstance.py:1283} INFO - 
--------------------------------------------------------------------------------
[2023-01-06T11:23:31.502+0530] {taskinstance.py:1284} INFO - Starting attempt 4 of 4
[2023-01-06T11:23:31.502+0530] {taskinstance.py:1285} INFO - 
--------------------------------------------------------------------------------
[2023-01-06T11:23:31.537+0530] {taskinstance.py:1304} INFO - Executing <Task(PythonOperator): load> on 2023-01-05 00:00:00+00:00
[2023-01-06T11:23:31.548+0530] {standard_task_runner.py:55} INFO - Started process 1115 to run task
[2023-01-06T11:23:31.553+0530] {standard_task_runner.py:82} INFO - Running: ['airflow', 'tasks', 'run', 'Monthly', 'load', 'scheduled__2023-01-05T00:00:00+00:00', '--job-id', '2908', '--raw', '--subdir', 'DAGS_FOLDER/Monthly.py', '--cfg-path', '/tmp/tmp5u33yief']
[2023-01-06T11:23:31.558+0530] {standard_task_runner.py:83} INFO - Job 2908: Subtask load
[2023-01-06T11:23:31.778+0530] {task_command.py:389} INFO - Running <TaskInstance: Monthly.load scheduled__2023-01-05T00:00:00+00:00 [running]> on host DESKTOP-SQIOQPD.
[2023-01-06T11:23:31.923+0530] {taskinstance.py:1511} INFO - Exporting the following env vars:
AIRFLOW_CTX_DAG_EMAIL=nikheleshbhattacharyya@gmail.com
AIRFLOW_CTX_DAG_OWNER=airflow
AIRFLOW_CTX_DAG_ID=Monthly
AIRFLOW_CTX_TASK_ID=load
AIRFLOW_CTX_EXECUTION_DATE=2023-01-05T00:00:00+00:00
AIRFLOW_CTX_TRY_NUMBER=4
AIRFLOW_CTX_DAG_RUN_ID=scheduled__2023-01-05T00:00:00+00:00
[2023-01-06T11:23:31.940+0530] {taskinstance.py:1772} ERROR - Task failed with exception
Traceback (most recent call last):
  File "/usr/local/lib/python3.8/dist-packages/airflow/operators/python.py", line 175, in execute
    return_value = self.execute_callable()
  File "/usr/local/lib/python3.8/dist-packages/airflow/operators/python.py", line 192, in execute_callable
    return self.python_callable(*self.op_args, **self.op_kwargs)
  File "/root/airflow/dags/Monthly.py", line 441, in load
    b4 = list(context['ti'].xcom_pull(task_ids='extract')[0])
TypeError: 'NoneType' object is not subscriptable
[2023-01-06T11:23:31.946+0530] {taskinstance.py:1322} INFO - Marking task as FAILED. dag_id=Monthly, task_id=load, execution_date=20230105T000000, start_date=20230106T055331, end_date=20230106T055331
[2023-01-06T11:23:31.980+0530] {logging_mixin.py:137} WARNING - /usr/local/lib/python3.8/dist-packages/airflow/utils/email.py:120 RemovedInAirflow3Warning: Fetching SMTP credentials from configuration variables will be deprecated in a future release. Please set credentials using a connection instead.
[2023-01-06T11:23:31.981+0530] {configuration.py:635} WARNING - section/key [smtp/smtp_user] not found in config
[2023-01-06T11:23:31.982+0530] {email.py:229} INFO - Email alerting: attempt 1
[2023-01-06T11:23:31.988+0530] {configuration.py:635} WARNING - section/key [smtp/smtp_user] not found in config
[2023-01-06T11:23:31.988+0530] {email.py:229} INFO - Email alerting: attempt 1
[2023-01-06T11:23:31.989+0530] {taskinstance.py:1835} ERROR - Failed to send email to: ['nikheleshbhattacharyya@gmail.com']
Traceback (most recent call last):
  File "/usr/local/lib/python3.8/dist-packages/airflow/models/taskinstance.py", line 1378, in _run_raw_task
    self._execute_task_with_callbacks(context, test_mode)
  File "/usr/local/lib/python3.8/dist-packages/airflow/models/taskinstance.py", line 1524, in _execute_task_with_callbacks
    result = self._execute_task(context, task_orig)
  File "/usr/local/lib/python3.8/dist-packages/airflow/models/taskinstance.py", line 1585, in _execute_task
    result = execute_callable(context=context)
  File "/usr/local/lib/python3.8/dist-packages/airflow/operators/python.py", line 175, in execute
    return_value = self.execute_callable()
  File "/usr/local/lib/python3.8/dist-packages/airflow/operators/python.py", line 192, in execute_callable
    return self.python_callable(*self.op_args, **self.op_kwargs)
  File "/root/airflow/dags/Monthly.py", line 441, in load
    b4 = list(context['ti'].xcom_pull(task_ids='extract')[0])
TypeError: 'NoneType' object is not subscriptable

During handling of the above exception, another exception occurred:

Traceback (most recent call last):
  File "/usr/local/lib/python3.8/dist-packages/airflow/models/taskinstance.py", line 2235, in email_alert
    send_email(task.email, subject, html_content)
  File "/usr/local/lib/python3.8/dist-packages/airflow/utils/email.py", line 59, in send_email
    return backend(
  File "/usr/local/lib/python3.8/dist-packages/airflow/utils/email.py", line 120, in send_email_smtp
    send_mime_email(e_from=mail_from, e_to=recipients, mime_msg=msg, conn_id=conn_id, dryrun=dryrun)
  File "/usr/local/lib/python3.8/dist-packages/airflow/utils/email.py", line 231, in send_mime_email
    smtp_conn = _get_smtp_connection(smtp_host, smtp_port, smtp_timeout, smtp_ssl)
  File "/usr/local/lib/python3.8/dist-packages/airflow/utils/email.py", line 265, in _get_smtp_connection
    else smtplib.SMTP(host=host, port=port, timeout=timeout)
  File "/usr/lib/python3.8/smtplib.py", line 255, in __init__
    (code, msg) = self.connect(host, port)
  File "/usr/lib/python3.8/smtplib.py", line 339, in connect
    self.sock = self._get_socket(host, port, self.timeout)
  File "/usr/lib/python3.8/smtplib.py", line 310, in _get_socket
    return socket.create_connection((host, port), timeout,
  File "/usr/lib/python3.8/socket.py", line 808, in create_connection
    raise err
  File "/usr/lib/python3.8/socket.py", line 796, in create_connection
    sock.connect(sa)
ConnectionRefusedError: [Errno 111] Connection refused

During handling of the above exception, another exception occurred:

Traceback (most recent call last):
  File "/usr/local/lib/python3.8/dist-packages/airflow/models/taskinstance.py", line 1833, in handle_failure
    self.email_alert(error, task)
  File "/usr/local/lib/python3.8/dist-packages/airflow/models/taskinstance.py", line 2237, in email_alert
    send_email(task.email, subject, html_content_err)
  File "/usr/local/lib/python3.8/dist-packages/airflow/utils/email.py", line 59, in send_email
    return backend(
  File "/usr/local/lib/python3.8/dist-packages/airflow/utils/email.py", line 120, in send_email_smtp
    send_mime_email(e_from=mail_from, e_to=recipients, mime_msg=msg, conn_id=conn_id, dryrun=dryrun)
  File "/usr/local/lib/python3.8/dist-packages/airflow/utils/email.py", line 231, in send_mime_email
    smtp_conn = _get_smtp_connection(smtp_host, smtp_port, smtp_timeout, smtp_ssl)
  File "/usr/local/lib/python3.8/dist-packages/airflow/utils/email.py", line 265, in _get_smtp_connection
    else smtplib.SMTP(host=host, port=port, timeout=timeout)
  File "/usr/lib/python3.8/smtplib.py", line 255, in __init__
    (code, msg) = self.connect(host, port)
  File "/usr/lib/python3.8/smtplib.py", line 339, in connect
    self.sock = self._get_socket(host, port, self.timeout)
  File "/usr/lib/python3.8/smtplib.py", line 310, in _get_socket
    return socket.create_connection((host, port), timeout,
  File "/usr/lib/python3.8/socket.py", line 808, in create_connection
    raise err
  File "/usr/lib/python3.8/socket.py", line 796, in create_connection
    sock.connect(sa)
ConnectionRefusedError: [Errno 111] Connection refused
[2023-01-06T11:23:32.012+0530] {standard_task_runner.py:100} ERROR - Failed to execute job 2908 for task load ('NoneType' object is not subscriptable; 1115)
[2023-01-06T11:23:32.054+0530] {local_task_job.py:159} INFO - Task exited with return code 1
[2023-01-06T11:23:32.080+0530] {taskinstance.py:2582} INFO - 0 downstream tasks scheduled from follow-on schedule check
