[2023-01-07T11:10:56.148+0530] {taskinstance.py:1087} INFO - Dependencies all met for <TaskInstance: Monthly.extract scheduled__2023-01-06T00:00:00+00:00 [queued]>
[2023-01-07T11:10:56.175+0530] {taskinstance.py:1087} INFO - Dependencies all met for <TaskInstance: Monthly.extract scheduled__2023-01-06T00:00:00+00:00 [queued]>
[2023-01-07T11:10:56.175+0530] {taskinstance.py:1283} INFO - 
--------------------------------------------------------------------------------
[2023-01-07T11:10:56.175+0530] {taskinstance.py:1284} INFO - Starting attempt 2 of 4
[2023-01-07T11:10:56.176+0530] {taskinstance.py:1285} INFO - 
--------------------------------------------------------------------------------
[2023-01-07T11:10:56.212+0530] {taskinstance.py:1304} INFO - Executing <Task(PythonOperator): extract> on 2023-01-06 00:00:00+00:00
[2023-01-07T11:10:56.241+0530] {standard_task_runner.py:55} INFO - Started process 5113 to run task
[2023-01-07T11:10:56.250+0530] {standard_task_runner.py:82} INFO - Running: ['airflow', 'tasks', 'run', 'Monthly', 'extract', 'scheduled__2023-01-06T00:00:00+00:00', '--job-id', '2939', '--raw', '--subdir', 'DAGS_FOLDER/Monthly.py', '--cfg-path', '/tmp/tmpbb2ry18m']
[2023-01-07T11:10:56.253+0530] {standard_task_runner.py:83} INFO - Job 2939: Subtask extract
[2023-01-07T11:10:56.398+0530] {task_command.py:389} INFO - Running <TaskInstance: Monthly.extract scheduled__2023-01-06T00:00:00+00:00 [running]> on host DESKTOP-SQIOQPD.
[2023-01-07T11:10:56.575+0530] {taskinstance.py:1511} INFO - Exporting the following env vars:
AIRFLOW_CTX_DAG_EMAIL=nikheleshbhattacharyya@gmail.com
AIRFLOW_CTX_DAG_OWNER=airflow
AIRFLOW_CTX_DAG_ID=Monthly
AIRFLOW_CTX_TASK_ID=extract
AIRFLOW_CTX_EXECUTION_DATE=2023-01-06T00:00:00+00:00
AIRFLOW_CTX_TRY_NUMBER=2
AIRFLOW_CTX_DAG_RUN_ID=scheduled__2023-01-06T00:00:00+00:00
[2023-01-07T11:11:09.379+0530] {taskinstance.py:1772} ERROR - Task failed with exception
Traceback (most recent call last):
  File "/usr/local/lib/python3.8/dist-packages/airflow/operators/python.py", line 175, in execute
    return_value = self.execute_callable()
  File "/usr/local/lib/python3.8/dist-packages/airflow/operators/python.py", line 192, in execute_callable
    return self.python_callable(*self.op_args, **self.op_kwargs)
  File "/root/airflow/dags/Monthly.py", line 418, in extract
    driver.get(url)
  File "/usr/local/lib/python3.8/dist-packages/selenium/webdriver/remote/webdriver.py", line 455, in get
    self.execute(Command.GET, {"url": url})
  File "/usr/local/lib/python3.8/dist-packages/selenium/webdriver/remote/webdriver.py", line 444, in execute
    self.error_handler.check_response(response)
  File "/usr/local/lib/python3.8/dist-packages/selenium/webdriver/remote/errorhandler.py", line 249, in check_response
    raise exception_class(message, screen, stacktrace)
selenium.common.exceptions.WebDriverException: Message: unknown error: net::ERR_NAME_NOT_RESOLVED
  (Session info: headless chrome=108.0.5359.124)
Stacktrace:
#0 0x55c2e71aa2a3 <unknown>
#1 0x55c2e6f68f77 <unknown>
#2 0x55c2e6f60e35 <unknown>
#3 0x55c2e6f53f27 <unknown>
#4 0x55c2e6f552d9 <unknown>
#5 0x55c2e6f5429e <unknown>
#6 0x55c2e6f533d2 <unknown>
#7 0x55c2e6f53225 <unknown>
#8 0x55c2e6f51dc6 <unknown>
#9 0x55c2e6f52244 <unknown>
#10 0x55c2e6f6ae88 <unknown>
#11 0x55c2e6fddb05 <unknown>
#12 0x55c2e6fc5b32 <unknown>
#13 0x55c2e6fdd47c <unknown>
#14 0x55c2e6fc5903 <unknown>
#15 0x55c2e6f98ece <unknown>
#16 0x55c2e6f99fde <unknown>
#17 0x55c2e71fa63e <unknown>
#18 0x55c2e71fdb79 <unknown>
#19 0x55c2e71e089e <unknown>
#20 0x55c2e71fea83 <unknown>
#21 0x55c2e71d3505 <unknown>
#22 0x55c2e721fca8 <unknown>
#23 0x55c2e721fe36 <unknown>
#24 0x55c2e723b333 <unknown>
#25 0x7f762db14609 start_thread

[2023-01-07T11:11:09.413+0530] {taskinstance.py:1322} INFO - Marking task as UP_FOR_RETRY. dag_id=Monthly, task_id=extract, execution_date=20230106T000000, start_date=20230107T054056, end_date=20230107T054109
[2023-01-07T11:11:09.464+0530] {standard_task_runner.py:100} ERROR - Failed to execute job 2939 for task extract (Message: unknown error: net::ERR_NAME_NOT_RESOLVED
  (Session info: headless chrome=108.0.5359.124)
Stacktrace:
#0 0x55c2e71aa2a3 <unknown>
#1 0x55c2e6f68f77 <unknown>
#2 0x55c2e6f60e35 <unknown>
#3 0x55c2e6f53f27 <unknown>
#4 0x55c2e6f552d9 <unknown>
#5 0x55c2e6f5429e <unknown>
#6 0x55c2e6f533d2 <unknown>
#7 0x55c2e6f53225 <unknown>
#8 0x55c2e6f51dc6 <unknown>
#9 0x55c2e6f52244 <unknown>
#10 0x55c2e6f6ae88 <unknown>
#11 0x55c2e6fddb05 <unknown>
#12 0x55c2e6fc5b32 <unknown>
#13 0x55c2e6fdd47c <unknown>
#14 0x55c2e6fc5903 <unknown>
#15 0x55c2e6f98ece <unknown>
#16 0x55c2e6f99fde <unknown>
#17 0x55c2e71fa63e <unknown>
#18 0x55c2e71fdb79 <unknown>
#19 0x55c2e71e089e <unknown>
#20 0x55c2e71fea83 <unknown>
#21 0x55c2e71d3505 <unknown>
#22 0x55c2e721fca8 <unknown>
#23 0x55c2e721fe36 <unknown>
#24 0x55c2e723b333 <unknown>
#25 0x7f762db14609 start_thread
; 5113)
[2023-01-07T11:11:09.489+0530] {local_task_job.py:159} INFO - Task exited with return code 1
[2023-01-07T11:11:09.529+0530] {taskinstance.py:2582} INFO - 0 downstream tasks scheduled from follow-on schedule check
