[2023-01-07T11:13:52.495+0530] {taskinstance.py:1087} INFO - Dependencies all met for <TaskInstance: Monthly.extract scheduled__2023-01-06T00:00:00+00:00 [queued]>
[2023-01-07T11:13:52.523+0530] {taskinstance.py:1087} INFO - Dependencies all met for <TaskInstance: Monthly.extract scheduled__2023-01-06T00:00:00+00:00 [queued]>
[2023-01-07T11:13:52.524+0530] {taskinstance.py:1283} INFO - 
--------------------------------------------------------------------------------
[2023-01-07T11:13:52.524+0530] {taskinstance.py:1284} INFO - Starting attempt 3 of 4
[2023-01-07T11:13:52.524+0530] {taskinstance.py:1285} INFO - 
--------------------------------------------------------------------------------
[2023-01-07T11:13:52.554+0530] {taskinstance.py:1304} INFO - Executing <Task(PythonOperator): extract> on 2023-01-06 00:00:00+00:00
[2023-01-07T11:13:52.566+0530] {standard_task_runner.py:55} INFO - Started process 5518 to run task
[2023-01-07T11:13:52.574+0530] {standard_task_runner.py:82} INFO - Running: ['airflow', 'tasks', 'run', 'Monthly', 'extract', 'scheduled__2023-01-06T00:00:00+00:00', '--job-id', '2945', '--raw', '--subdir', 'DAGS_FOLDER/Monthly.py', '--cfg-path', '/tmp/tmp79b_hjvp']
[2023-01-07T11:13:52.576+0530] {standard_task_runner.py:83} INFO - Job 2945: Subtask extract
[2023-01-07T11:13:52.664+0530] {task_command.py:389} INFO - Running <TaskInstance: Monthly.extract scheduled__2023-01-06T00:00:00+00:00 [running]> on host DESKTOP-SQIOQPD.
[2023-01-07T11:13:52.936+0530] {taskinstance.py:1511} INFO - Exporting the following env vars:
AIRFLOW_CTX_DAG_EMAIL=nikheleshbhattacharyya@gmail.com
AIRFLOW_CTX_DAG_OWNER=airflow
AIRFLOW_CTX_DAG_ID=Monthly
AIRFLOW_CTX_TASK_ID=extract
AIRFLOW_CTX_EXECUTION_DATE=2023-01-06T00:00:00+00:00
AIRFLOW_CTX_TRY_NUMBER=3
AIRFLOW_CTX_DAG_RUN_ID=scheduled__2023-01-06T00:00:00+00:00
[2023-01-07T11:15:00.334+0530] {taskinstance.py:1772} ERROR - Task failed with exception
Traceback (most recent call last):
  File "/usr/local/lib/python3.8/dist-packages/airflow/operators/python.py", line 175, in execute
    return_value = self.execute_callable()
  File "/usr/local/lib/python3.8/dist-packages/airflow/operators/python.py", line 192, in execute_callable
    return self.python_callable(*self.op_args, **self.op_kwargs)
  File "/root/airflow/dags/Monthly.py", line 416, in extract
    driver = webdriver.Chrome('/usr/local/bin/chromedriver',options=chrome_options)
  File "/usr/local/lib/python3.8/dist-packages/selenium/webdriver/chrome/webdriver.py", line 81, in __init__
    super().__init__(
  File "/usr/local/lib/python3.8/dist-packages/selenium/webdriver/chromium/webdriver.py", line 106, in __init__
    super().__init__(
  File "/usr/local/lib/python3.8/dist-packages/selenium/webdriver/remote/webdriver.py", line 288, in __init__
    self.start_session(capabilities, browser_profile)
  File "/usr/local/lib/python3.8/dist-packages/selenium/webdriver/remote/webdriver.py", line 381, in start_session
    response = self.execute(Command.NEW_SESSION, parameters)
  File "/usr/local/lib/python3.8/dist-packages/selenium/webdriver/remote/webdriver.py", line 444, in execute
    self.error_handler.check_response(response)
  File "/usr/local/lib/python3.8/dist-packages/selenium/webdriver/remote/errorhandler.py", line 249, in check_response
    raise exception_class(message, screen, stacktrace)
selenium.common.exceptions.WebDriverException: Message: chrome not reachable
Stacktrace:
#0 0x558b4057f2a3 <unknown>
#1 0x558b4033ddfd <unknown>
#2 0x558b4032c14b <unknown>
#3 0x558b4036a843 <unknown>
#4 0x558b40365cae <unknown>
#5 0x558b403627d0 <unknown>
#6 0x558b403a30b7 <unknown>
#7 0x558b403a2a5f <unknown>
#8 0x558b4039a903 <unknown>
#9 0x558b4036dece <unknown>
#10 0x558b4036efde <unknown>
#11 0x558b405cf63e <unknown>
#12 0x558b405d2b79 <unknown>
#13 0x558b405b589e <unknown>
#14 0x558b405d3a83 <unknown>
#15 0x558b405a8505 <unknown>
#16 0x558b405f4ca8 <unknown>
#17 0x558b405f4e36 <unknown>
#18 0x558b40610333 <unknown>
#19 0x7f8291ace609 start_thread

[2023-01-07T11:15:00.619+0530] {taskinstance.py:1322} INFO - Marking task as UP_FOR_RETRY. dag_id=Monthly, task_id=extract, execution_date=20230106T000000, start_date=20230107T054352, end_date=20230107T054500
[2023-01-07T11:15:00.852+0530] {standard_task_runner.py:100} ERROR - Failed to execute job 2945 for task extract (Message: chrome not reachable
Stacktrace:
#0 0x558b4057f2a3 <unknown>
#1 0x558b4033ddfd <unknown>
#2 0x558b4032c14b <unknown>
#3 0x558b4036a843 <unknown>
#4 0x558b40365cae <unknown>
#5 0x558b403627d0 <unknown>
#6 0x558b403a30b7 <unknown>
#7 0x558b403a2a5f <unknown>
#8 0x558b4039a903 <unknown>
#9 0x558b4036dece <unknown>
#10 0x558b4036efde <unknown>
#11 0x558b405cf63e <unknown>
#12 0x558b405d2b79 <unknown>
#13 0x558b405b589e <unknown>
#14 0x558b405d3a83 <unknown>
#15 0x558b405a8505 <unknown>
#16 0x558b405f4ca8 <unknown>
#17 0x558b405f4e36 <unknown>
#18 0x558b40610333 <unknown>
#19 0x7f8291ace609 start_thread
; 5518)
[2023-01-07T11:15:00.919+0530] {local_task_job.py:159} INFO - Task exited with return code 1
[2023-01-07T11:15:01.016+0530] {taskinstance.py:2582} INFO - 0 downstream tasks scheduled from follow-on schedule check
