[2023-01-06T11:17:35.859+0530] {taskinstance.py:1087} INFO - Dependencies all met for <TaskInstance: FX__Turnover.extract scheduled__2023-01-05T00:00:00+00:00 [queued]>
[2023-01-06T11:17:35.894+0530] {taskinstance.py:1087} INFO - Dependencies all met for <TaskInstance: FX__Turnover.extract scheduled__2023-01-05T00:00:00+00:00 [queued]>
[2023-01-06T11:17:35.894+0530] {taskinstance.py:1283} INFO - 
--------------------------------------------------------------------------------
[2023-01-06T11:17:35.894+0530] {taskinstance.py:1284} INFO - Starting attempt 1 of 4
[2023-01-06T11:17:35.895+0530] {taskinstance.py:1285} INFO - 
--------------------------------------------------------------------------------
[2023-01-06T11:17:35.927+0530] {taskinstance.py:1304} INFO - Executing <Task(PythonOperator): extract> on 2023-01-05 00:00:00+00:00
[2023-01-06T11:17:35.940+0530] {standard_task_runner.py:55} INFO - Started process 32434 to run task
[2023-01-06T11:17:35.947+0530] {standard_task_runner.py:82} INFO - Running: ['airflow', 'tasks', 'run', 'FX__Turnover', 'extract', 'scheduled__2023-01-05T00:00:00+00:00', '--job-id', '2892', '--raw', '--subdir', 'DAGS_FOLDER/FX_turnover.py', '--cfg-path', '/tmp/tmpvxhd3mg4']
[2023-01-06T11:17:35.951+0530] {standard_task_runner.py:83} INFO - Job 2892: Subtask extract
[2023-01-06T11:17:36.102+0530] {task_command.py:389} INFO - Running <TaskInstance: FX__Turnover.extract scheduled__2023-01-05T00:00:00+00:00 [running]> on host DESKTOP-SQIOQPD.
[2023-01-06T11:17:36.277+0530] {taskinstance.py:1511} INFO - Exporting the following env vars:
AIRFLOW_CTX_DAG_EMAIL=nikheleshbhattacharyya@gmail.com
AIRFLOW_CTX_DAG_OWNER=airflow
AIRFLOW_CTX_DAG_ID=FX__Turnover
AIRFLOW_CTX_TASK_ID=extract
AIRFLOW_CTX_EXECUTION_DATE=2023-01-05T00:00:00+00:00
AIRFLOW_CTX_TRY_NUMBER=1
AIRFLOW_CTX_DAG_RUN_ID=scheduled__2023-01-05T00:00:00+00:00
[2023-01-06T11:17:47.396+0530] {taskinstance.py:1772} ERROR - Task failed with exception
Traceback (most recent call last):
  File "/usr/local/lib/python3.8/dist-packages/airflow/operators/python.py", line 175, in execute
    return_value = self.execute_callable()
  File "/usr/local/lib/python3.8/dist-packages/airflow/operators/python.py", line 192, in execute_callable
    return self.python_callable(*self.op_args, **self.op_kwargs)
  File "/root/airflow/dags/FX_turnover.py", line 139, in extract_fxturn
    driver.get(url)
  File "/usr/local/lib/python3.8/dist-packages/selenium/webdriver/remote/webdriver.py", line 455, in get
    self.execute(Command.GET, {"url": url})
  File "/usr/local/lib/python3.8/dist-packages/selenium/webdriver/remote/webdriver.py", line 444, in execute
    self.error_handler.check_response(response)
  File "/usr/local/lib/python3.8/dist-packages/selenium/webdriver/remote/errorhandler.py", line 249, in check_response
    raise exception_class(message, screen, stacktrace)
selenium.common.exceptions.WebDriverException: Message: unknown error: net::ERR_NAME_NOT_RESOLVED
  (Session info: headless chrome=108.0.5359.124)
Stacktrace:
#0 0x56285a8f92a3 <unknown>
#1 0x56285a6b7f77 <unknown>
#2 0x56285a6afe35 <unknown>
#3 0x56285a6a2f27 <unknown>
#4 0x56285a6a42d9 <unknown>
#5 0x56285a6a329e <unknown>
#6 0x56285a6a23d2 <unknown>
#7 0x56285a6a2225 <unknown>
#8 0x56285a6a0dc6 <unknown>
#9 0x56285a6a1244 <unknown>
#10 0x56285a6b9e88 <unknown>
#11 0x56285a72cb05 <unknown>
#12 0x56285a714b32 <unknown>
#13 0x56285a72c47c <unknown>
#14 0x56285a714903 <unknown>
#15 0x56285a6e7ece <unknown>
#16 0x56285a6e8fde <unknown>
#17 0x56285a94963e <unknown>
#18 0x56285a94cb79 <unknown>
#19 0x56285a92f89e <unknown>
#20 0x56285a94da83 <unknown>
#21 0x56285a922505 <unknown>
#22 0x56285a96eca8 <unknown>
#23 0x56285a96ee36 <unknown>
#24 0x56285a98a333 <unknown>
#25 0x7f8b35c9e609 start_thread

[2023-01-06T11:17:47.408+0530] {taskinstance.py:1322} INFO - Marking task as UP_FOR_RETRY. dag_id=FX__Turnover, task_id=extract, execution_date=20230105T000000, start_date=20230106T054735, end_date=20230106T054747
[2023-01-06T11:17:47.431+0530] {standard_task_runner.py:100} ERROR - Failed to execute job 2892 for task extract (Message: unknown error: net::ERR_NAME_NOT_RESOLVED
  (Session info: headless chrome=108.0.5359.124)
Stacktrace:
#0 0x56285a8f92a3 <unknown>
#1 0x56285a6b7f77 <unknown>
#2 0x56285a6afe35 <unknown>
#3 0x56285a6a2f27 <unknown>
#4 0x56285a6a42d9 <unknown>
#5 0x56285a6a329e <unknown>
#6 0x56285a6a23d2 <unknown>
#7 0x56285a6a2225 <unknown>
#8 0x56285a6a0dc6 <unknown>
#9 0x56285a6a1244 <unknown>
#10 0x56285a6b9e88 <unknown>
#11 0x56285a72cb05 <unknown>
#12 0x56285a714b32 <unknown>
#13 0x56285a72c47c <unknown>
#14 0x56285a714903 <unknown>
#15 0x56285a6e7ece <unknown>
#16 0x56285a6e8fde <unknown>
#17 0x56285a94963e <unknown>
#18 0x56285a94cb79 <unknown>
#19 0x56285a92f89e <unknown>
#20 0x56285a94da83 <unknown>
#21 0x56285a922505 <unknown>
#22 0x56285a96eca8 <unknown>
#23 0x56285a96ee36 <unknown>
#24 0x56285a98a333 <unknown>
#25 0x7f8b35c9e609 start_thread
; 32434)
[2023-01-06T11:17:47.468+0530] {local_task_job.py:159} INFO - Task exited with return code 1
[2023-01-06T11:17:47.512+0530] {taskinstance.py:2582} INFO - 0 downstream tasks scheduled from follow-on schedule check
