[2023-01-06T11:20:53.943+0530] {taskinstance.py:1087} INFO - Dependencies all met for <TaskInstance: Monthly.extract scheduled__2023-01-05T00:00:00+00:00 [queued]>
[2023-01-06T11:20:53.966+0530] {taskinstance.py:1087} INFO - Dependencies all met for <TaskInstance: Monthly.extract scheduled__2023-01-05T00:00:00+00:00 [queued]>
[2023-01-06T11:20:53.967+0530] {taskinstance.py:1283} INFO - 
--------------------------------------------------------------------------------
[2023-01-06T11:20:53.967+0530] {taskinstance.py:1284} INFO - Starting attempt 2 of 4
[2023-01-06T11:20:53.967+0530] {taskinstance.py:1285} INFO - 
--------------------------------------------------------------------------------
[2023-01-06T11:20:54.001+0530] {taskinstance.py:1304} INFO - Executing <Task(PythonOperator): extract> on 2023-01-05 00:00:00+00:00
[2023-01-06T11:20:54.012+0530] {standard_task_runner.py:55} INFO - Started process 594 to run task
[2023-01-06T11:20:54.019+0530] {standard_task_runner.py:82} INFO - Running: ['airflow', 'tasks', 'run', 'Monthly', 'extract', 'scheduled__2023-01-05T00:00:00+00:00', '--job-id', '2901', '--raw', '--subdir', 'DAGS_FOLDER/Monthly.py', '--cfg-path', '/tmp/tmpc69r_206']
[2023-01-06T11:20:54.022+0530] {standard_task_runner.py:83} INFO - Job 2901: Subtask extract
[2023-01-06T11:20:54.102+0530] {task_command.py:389} INFO - Running <TaskInstance: Monthly.extract scheduled__2023-01-05T00:00:00+00:00 [running]> on host DESKTOP-SQIOQPD.
[2023-01-06T11:20:54.209+0530] {taskinstance.py:1511} INFO - Exporting the following env vars:
AIRFLOW_CTX_DAG_EMAIL=nikheleshbhattacharyya@gmail.com
AIRFLOW_CTX_DAG_OWNER=airflow
AIRFLOW_CTX_DAG_ID=Monthly
AIRFLOW_CTX_TASK_ID=extract
AIRFLOW_CTX_EXECUTION_DATE=2023-01-05T00:00:00+00:00
AIRFLOW_CTX_TRY_NUMBER=2
AIRFLOW_CTX_DAG_RUN_ID=scheduled__2023-01-05T00:00:00+00:00
[2023-01-06T11:21:06.713+0530] {taskinstance.py:1772} ERROR - Task failed with exception
Traceback (most recent call last):
  File "/usr/local/lib/python3.8/dist-packages/airflow/operators/python.py", line 175, in execute
    return_value = self.execute_callable()
  File "/usr/local/lib/python3.8/dist-packages/airflow/operators/python.py", line 192, in execute_callable
    return self.python_callable(*self.op_args, **self.op_kwargs)
  File "/root/airflow/dags/Monthly.py", line 418, in extract
    driver.get(url)
  File "/usr/local/lib/python3.8/dist-packages/selenium/webdriver/remote/webdriver.py", line 455, in get
    self.execute(Command.GET, {"url": url})
  File "/usr/local/lib/python3.8/dist-packages/selenium/webdriver/remote/webdriver.py", line 444, in execute
    self.error_handler.check_response(response)
  File "/usr/local/lib/python3.8/dist-packages/selenium/webdriver/remote/errorhandler.py", line 249, in check_response
    raise exception_class(message, screen, stacktrace)
selenium.common.exceptions.WebDriverException: Message: unknown error: net::ERR_NAME_NOT_RESOLVED
  (Session info: headless chrome=108.0.5359.124)
Stacktrace:
#0 0x55dae2d002a3 <unknown>
#1 0x55dae2abef77 <unknown>
#2 0x55dae2ab6e35 <unknown>
#3 0x55dae2aa9f27 <unknown>
#4 0x55dae2aab2d9 <unknown>
#5 0x55dae2aaa29e <unknown>
#6 0x55dae2aa93d2 <unknown>
#7 0x55dae2aa9225 <unknown>
#8 0x55dae2aa7dc6 <unknown>
#9 0x55dae2aa8244 <unknown>
#10 0x55dae2ac0e88 <unknown>
#11 0x55dae2b33b05 <unknown>
#12 0x55dae2b1bb32 <unknown>
#13 0x55dae2b3347c <unknown>
#14 0x55dae2b1b903 <unknown>
#15 0x55dae2aeeece <unknown>
#16 0x55dae2aeffde <unknown>
#17 0x55dae2d5063e <unknown>
#18 0x55dae2d53b79 <unknown>
#19 0x55dae2d3689e <unknown>
#20 0x55dae2d54a83 <unknown>
#21 0x55dae2d29505 <unknown>
#22 0x55dae2d75ca8 <unknown>
#23 0x55dae2d75e36 <unknown>
#24 0x55dae2d91333 <unknown>
#25 0x7f1dbc78c609 start_thread

[2023-01-06T11:21:06.789+0530] {taskinstance.py:1322} INFO - Marking task as UP_FOR_RETRY. dag_id=Monthly, task_id=extract, execution_date=20230105T000000, start_date=20230106T055053, end_date=20230106T055106
[2023-01-06T11:21:06.834+0530] {standard_task_runner.py:100} ERROR - Failed to execute job 2901 for task extract (Message: unknown error: net::ERR_NAME_NOT_RESOLVED
  (Session info: headless chrome=108.0.5359.124)
Stacktrace:
#0 0x55dae2d002a3 <unknown>
#1 0x55dae2abef77 <unknown>
#2 0x55dae2ab6e35 <unknown>
#3 0x55dae2aa9f27 <unknown>
#4 0x55dae2aab2d9 <unknown>
#5 0x55dae2aaa29e <unknown>
#6 0x55dae2aa93d2 <unknown>
#7 0x55dae2aa9225 <unknown>
#8 0x55dae2aa7dc6 <unknown>
#9 0x55dae2aa8244 <unknown>
#10 0x55dae2ac0e88 <unknown>
#11 0x55dae2b33b05 <unknown>
#12 0x55dae2b1bb32 <unknown>
#13 0x55dae2b3347c <unknown>
#14 0x55dae2b1b903 <unknown>
#15 0x55dae2aeeece <unknown>
#16 0x55dae2aeffde <unknown>
#17 0x55dae2d5063e <unknown>
#18 0x55dae2d53b79 <unknown>
#19 0x55dae2d3689e <unknown>
#20 0x55dae2d54a83 <unknown>
#21 0x55dae2d29505 <unknown>
#22 0x55dae2d75ca8 <unknown>
#23 0x55dae2d75e36 <unknown>
#24 0x55dae2d91333 <unknown>
#25 0x7f1dbc78c609 start_thread
; 594)
[2023-01-06T11:21:06.883+0530] {local_task_job.py:159} INFO - Task exited with return code 1
[2023-01-06T11:21:06.917+0530] {taskinstance.py:2582} INFO - 0 downstream tasks scheduled from follow-on schedule check
