[2023-01-06T11:18:24.924+0530] {taskinstance.py:1087} INFO - Dependencies all met for <TaskInstance: Monthly.extract scheduled__2023-01-05T00:00:00+00:00 [queued]>
[2023-01-06T11:18:24.939+0530] {taskinstance.py:1087} INFO - Dependencies all met for <TaskInstance: Monthly.extract scheduled__2023-01-05T00:00:00+00:00 [queued]>
[2023-01-06T11:18:24.940+0530] {taskinstance.py:1283} INFO - 
--------------------------------------------------------------------------------
[2023-01-06T11:18:24.940+0530] {taskinstance.py:1284} INFO - Starting attempt 1 of 4
[2023-01-06T11:18:24.940+0530] {taskinstance.py:1285} INFO - 
--------------------------------------------------------------------------------
[2023-01-06T11:18:24.969+0530] {taskinstance.py:1304} INFO - Executing <Task(PythonOperator): extract> on 2023-01-05 00:00:00+00:00
[2023-01-06T11:18:24.979+0530] {standard_task_runner.py:55} INFO - Started process 32635 to run task
[2023-01-06T11:18:24.984+0530] {standard_task_runner.py:82} INFO - Running: ['airflow', 'tasks', 'run', 'Monthly', 'extract', 'scheduled__2023-01-05T00:00:00+00:00', '--job-id', '2895', '--raw', '--subdir', 'DAGS_FOLDER/Monthly.py', '--cfg-path', '/tmp/tmpi1zxx_rd']
[2023-01-06T11:18:24.985+0530] {standard_task_runner.py:83} INFO - Job 2895: Subtask extract
[2023-01-06T11:18:25.063+0530] {task_command.py:389} INFO - Running <TaskInstance: Monthly.extract scheduled__2023-01-05T00:00:00+00:00 [running]> on host DESKTOP-SQIOQPD.
[2023-01-06T11:18:25.170+0530] {taskinstance.py:1511} INFO - Exporting the following env vars:
AIRFLOW_CTX_DAG_EMAIL=nikheleshbhattacharyya@gmail.com
AIRFLOW_CTX_DAG_OWNER=airflow
AIRFLOW_CTX_DAG_ID=Monthly
AIRFLOW_CTX_TASK_ID=extract
AIRFLOW_CTX_EXECUTION_DATE=2023-01-05T00:00:00+00:00
AIRFLOW_CTX_TRY_NUMBER=1
AIRFLOW_CTX_DAG_RUN_ID=scheduled__2023-01-05T00:00:00+00:00
[2023-01-06T11:18:36.372+0530] {taskinstance.py:1772} ERROR - Task failed with exception
Traceback (most recent call last):
  File "/usr/local/lib/python3.8/dist-packages/airflow/operators/python.py", line 175, in execute
    return_value = self.execute_callable()
  File "/usr/local/lib/python3.8/dist-packages/airflow/operators/python.py", line 192, in execute_callable
    return self.python_callable(*self.op_args, **self.op_kwargs)
  File "/root/airflow/dags/Monthly.py", line 418, in extract
    driver.get(url)
  File "/usr/local/lib/python3.8/dist-packages/selenium/webdriver/remote/webdriver.py", line 455, in get
    self.execute(Command.GET, {"url": url})
  File "/usr/local/lib/python3.8/dist-packages/selenium/webdriver/remote/webdriver.py", line 444, in execute
    self.error_handler.check_response(response)
  File "/usr/local/lib/python3.8/dist-packages/selenium/webdriver/remote/errorhandler.py", line 249, in check_response
    raise exception_class(message, screen, stacktrace)
selenium.common.exceptions.WebDriverException: Message: unknown error: net::ERR_NAME_NOT_RESOLVED
  (Session info: headless chrome=108.0.5359.124)
Stacktrace:
#0 0x5653681722a3 <unknown>
#1 0x565367f30f77 <unknown>
#2 0x565367f28e35 <unknown>
#3 0x565367f1bf27 <unknown>
#4 0x565367f1d2d9 <unknown>
#5 0x565367f1c29e <unknown>
#6 0x565367f1b3d2 <unknown>
#7 0x565367f1b225 <unknown>
#8 0x565367f19dc6 <unknown>
#9 0x565367f1a244 <unknown>
#10 0x565367f32e88 <unknown>
#11 0x565367fa5b05 <unknown>
#12 0x565367f8db32 <unknown>
#13 0x565367fa547c <unknown>
#14 0x565367f8d903 <unknown>
#15 0x565367f60ece <unknown>
#16 0x565367f61fde <unknown>
#17 0x5653681c263e <unknown>
#18 0x5653681c5b79 <unknown>
#19 0x5653681a889e <unknown>
#20 0x5653681c6a83 <unknown>
#21 0x56536819b505 <unknown>
#22 0x5653681e7ca8 <unknown>
#23 0x5653681e7e36 <unknown>
#24 0x565368203333 <unknown>
#25 0x7f60060f9609 start_thread

[2023-01-06T11:18:36.389+0530] {taskinstance.py:1322} INFO - Marking task as UP_FOR_RETRY. dag_id=Monthly, task_id=extract, execution_date=20230105T000000, start_date=20230106T054824, end_date=20230106T054836
[2023-01-06T11:18:36.425+0530] {standard_task_runner.py:100} ERROR - Failed to execute job 2895 for task extract (Message: unknown error: net::ERR_NAME_NOT_RESOLVED
  (Session info: headless chrome=108.0.5359.124)
Stacktrace:
#0 0x5653681722a3 <unknown>
#1 0x565367f30f77 <unknown>
#2 0x565367f28e35 <unknown>
#3 0x565367f1bf27 <unknown>
#4 0x565367f1d2d9 <unknown>
#5 0x565367f1c29e <unknown>
#6 0x565367f1b3d2 <unknown>
#7 0x565367f1b225 <unknown>
#8 0x565367f19dc6 <unknown>
#9 0x565367f1a244 <unknown>
#10 0x565367f32e88 <unknown>
#11 0x565367fa5b05 <unknown>
#12 0x565367f8db32 <unknown>
#13 0x565367fa547c <unknown>
#14 0x565367f8d903 <unknown>
#15 0x565367f60ece <unknown>
#16 0x565367f61fde <unknown>
#17 0x5653681c263e <unknown>
#18 0x5653681c5b79 <unknown>
#19 0x5653681a889e <unknown>
#20 0x5653681c6a83 <unknown>
#21 0x56536819b505 <unknown>
#22 0x5653681e7ca8 <unknown>
#23 0x5653681e7e36 <unknown>
#24 0x565368203333 <unknown>
#25 0x7f60060f9609 start_thread
; 32635)
[2023-01-06T11:18:36.454+0530] {local_task_job.py:159} INFO - Task exited with return code 1
[2023-01-06T11:18:36.494+0530] {taskinstance.py:2582} INFO - 0 downstream tasks scheduled from follow-on schedule check
