[2023-03-17T03:08:13.194+0530] {taskinstance.py:1087} INFO - Dependencies all met for <TaskInstance: FX__Turnover.extract scheduled__2023-02-24T00:00:00+00:00 [queued]>
[2023-03-17T03:08:13.204+0530] {taskinstance.py:1087} INFO - Dependencies all met for <TaskInstance: FX__Turnover.extract scheduled__2023-02-24T00:00:00+00:00 [queued]>
[2023-03-17T03:08:13.204+0530] {taskinstance.py:1283} INFO - 
--------------------------------------------------------------------------------
[2023-03-17T03:08:13.204+0530] {taskinstance.py:1284} INFO - Starting attempt 4 of 4
[2023-03-17T03:08:13.205+0530] {taskinstance.py:1285} INFO - 
--------------------------------------------------------------------------------
[2023-03-17T03:08:13.222+0530] {taskinstance.py:1304} INFO - Executing <Task(PythonOperator): extract> on 2023-02-24 00:00:00+00:00
[2023-03-17T03:08:13.231+0530] {standard_task_runner.py:55} INFO - Started process 3024 to run task
[2023-03-17T03:08:13.235+0530] {standard_task_runner.py:82} INFO - Running: ['airflow', 'tasks', 'run', 'FX__Turnover', 'extract', 'scheduled__2023-02-24T00:00:00+00:00', '--job-id', '4830', '--raw', '--subdir', 'DAGS_FOLDER/FX_turnover.py', '--cfg-path', '/tmp/tmpbzurbxlu']
[2023-03-17T03:08:13.237+0530] {standard_task_runner.py:83} INFO - Job 4830: Subtask extract
[2023-03-17T03:08:13.355+0530] {task_command.py:389} INFO - Running <TaskInstance: FX__Turnover.extract scheduled__2023-02-24T00:00:00+00:00 [running]> on host DESKTOP-SQIOQPD.
[2023-03-17T03:08:13.550+0530] {taskinstance.py:1511} INFO - Exporting the following env vars:
AIRFLOW_CTX_DAG_EMAIL=nikheleshbhattacharyya@gmail.com
AIRFLOW_CTX_DAG_OWNER=airflow
AIRFLOW_CTX_DAG_ID=FX__Turnover
AIRFLOW_CTX_TASK_ID=extract
AIRFLOW_CTX_EXECUTION_DATE=2023-02-24T00:00:00+00:00
AIRFLOW_CTX_TRY_NUMBER=4
AIRFLOW_CTX_DAG_RUN_ID=scheduled__2023-02-24T00:00:00+00:00
[2023-03-17T03:08:45.980+0530] {taskinstance.py:1772} ERROR - Task failed with exception
Traceback (most recent call last):
  File "/usr/local/lib/python3.8/dist-packages/airflow/operators/python.py", line 175, in execute
    return_value = self.execute_callable()
  File "/usr/local/lib/python3.8/dist-packages/airflow/operators/python.py", line 192, in execute_callable
    return self.python_callable(*self.op_args, **self.op_kwargs)
  File "/root/airflow/dags/FX_turnover.py", line 141, in extract_fxturn
    python_button1[0].click()
IndexError: list index out of range
[2023-03-17T03:08:45.988+0530] {taskinstance.py:1322} INFO - Marking task as FAILED. dag_id=FX__Turnover, task_id=extract, execution_date=20230224T000000, start_date=20230316T213813, end_date=20230316T213845
[2023-03-17T03:08:46.012+0530] {logging_mixin.py:137} WARNING - /usr/local/lib/python3.8/dist-packages/airflow/utils/email.py:120 RemovedInAirflow3Warning: Fetching SMTP credentials from configuration variables will be deprecated in a future release. Please set credentials using a connection instead.
[2023-03-17T03:08:46.012+0530] {email.py:229} INFO - Email alerting: attempt 1
[2023-03-17T03:09:16.061+0530] {email.py:229} INFO - Email alerting: attempt 1
[2023-03-17T03:09:46.091+0530] {taskinstance.py:1835} ERROR - Failed to send email to: ['nikheleshbhattacharyya@gmail.com']
Traceback (most recent call last):
  File "/usr/local/lib/python3.8/dist-packages/airflow/models/taskinstance.py", line 1378, in _run_raw_task
    self._execute_task_with_callbacks(context, test_mode)
  File "/usr/local/lib/python3.8/dist-packages/airflow/models/taskinstance.py", line 1524, in _execute_task_with_callbacks
    result = self._execute_task(context, task_orig)
  File "/usr/local/lib/python3.8/dist-packages/airflow/models/taskinstance.py", line 1585, in _execute_task
    result = execute_callable(context=context)
  File "/usr/local/lib/python3.8/dist-packages/airflow/operators/python.py", line 175, in execute
    return_value = self.execute_callable()
  File "/usr/local/lib/python3.8/dist-packages/airflow/operators/python.py", line 192, in execute_callable
    return self.python_callable(*self.op_args, **self.op_kwargs)
  File "/root/airflow/dags/FX_turnover.py", line 141, in extract_fxturn
    python_button1[0].click()
IndexError: list index out of range

During handling of the above exception, another exception occurred:

Traceback (most recent call last):
  File "/usr/local/lib/python3.8/dist-packages/airflow/models/taskinstance.py", line 2235, in email_alert
    send_email(task.email, subject, html_content)
  File "/usr/local/lib/python3.8/dist-packages/airflow/utils/email.py", line 59, in send_email
    return backend(
  File "/usr/local/lib/python3.8/dist-packages/airflow/utils/email.py", line 120, in send_email_smtp
    send_mime_email(e_from=mail_from, e_to=recipients, mime_msg=msg, conn_id=conn_id, dryrun=dryrun)
  File "/usr/local/lib/python3.8/dist-packages/airflow/utils/email.py", line 231, in send_mime_email
    smtp_conn = _get_smtp_connection(smtp_host, smtp_port, smtp_timeout, smtp_ssl)
  File "/usr/local/lib/python3.8/dist-packages/airflow/utils/email.py", line 265, in _get_smtp_connection
    else smtplib.SMTP(host=host, port=port, timeout=timeout)
  File "/usr/lib/python3.8/smtplib.py", line 255, in __init__
    (code, msg) = self.connect(host, port)
  File "/usr/lib/python3.8/smtplib.py", line 339, in connect
    self.sock = self._get_socket(host, port, self.timeout)
  File "/usr/lib/python3.8/smtplib.py", line 310, in _get_socket
    return socket.create_connection((host, port), timeout,
  File "/usr/lib/python3.8/socket.py", line 808, in create_connection
    raise err
  File "/usr/lib/python3.8/socket.py", line 796, in create_connection
    sock.connect(sa)
OSError: [Errno 101] Network is unreachable

During handling of the above exception, another exception occurred:

Traceback (most recent call last):
  File "/usr/local/lib/python3.8/dist-packages/airflow/models/taskinstance.py", line 1833, in handle_failure
    self.email_alert(error, task)
  File "/usr/local/lib/python3.8/dist-packages/airflow/models/taskinstance.py", line 2237, in email_alert
    send_email(task.email, subject, html_content_err)
  File "/usr/local/lib/python3.8/dist-packages/airflow/utils/email.py", line 59, in send_email
    return backend(
  File "/usr/local/lib/python3.8/dist-packages/airflow/utils/email.py", line 120, in send_email_smtp
    send_mime_email(e_from=mail_from, e_to=recipients, mime_msg=msg, conn_id=conn_id, dryrun=dryrun)
  File "/usr/local/lib/python3.8/dist-packages/airflow/utils/email.py", line 231, in send_mime_email
    smtp_conn = _get_smtp_connection(smtp_host, smtp_port, smtp_timeout, smtp_ssl)
  File "/usr/local/lib/python3.8/dist-packages/airflow/utils/email.py", line 265, in _get_smtp_connection
    else smtplib.SMTP(host=host, port=port, timeout=timeout)
  File "/usr/lib/python3.8/smtplib.py", line 255, in __init__
    (code, msg) = self.connect(host, port)
  File "/usr/lib/python3.8/smtplib.py", line 339, in connect
    self.sock = self._get_socket(host, port, self.timeout)
  File "/usr/lib/python3.8/smtplib.py", line 310, in _get_socket
    return socket.create_connection((host, port), timeout,
  File "/usr/lib/python3.8/socket.py", line 808, in create_connection
    raise err
  File "/usr/lib/python3.8/socket.py", line 796, in create_connection
    sock.connect(sa)
OSError: [Errno 101] Network is unreachable
[2023-03-17T03:09:46.120+0530] {standard_task_runner.py:100} ERROR - Failed to execute job 4830 for task extract (list index out of range; 3024)
[2023-03-17T03:09:46.163+0530] {local_task_job.py:159} INFO - Task exited with return code 1
[2023-03-17T03:09:46.186+0530] {taskinstance.py:2582} INFO - 0 downstream tasks scheduled from follow-on schedule check
