[2023-03-17T05:05:25.275+0530] {taskinstance.py:1087} INFO - Dependencies all met for <TaskInstance: nsdlfpi_and_rupee.extract_data scheduled__2023-03-02T00:00:00+00:00 [queued]>
[2023-03-17T05:05:25.292+0530] {taskinstance.py:1087} INFO - Dependencies all met for <TaskInstance: nsdlfpi_and_rupee.extract_data scheduled__2023-03-02T00:00:00+00:00 [queued]>
[2023-03-17T05:05:25.292+0530] {taskinstance.py:1283} INFO - 
--------------------------------------------------------------------------------
[2023-03-17T05:05:25.292+0530] {taskinstance.py:1284} INFO - Starting attempt 1 of 4
[2023-03-17T05:05:25.292+0530] {taskinstance.py:1285} INFO - 
--------------------------------------------------------------------------------
[2023-03-17T05:05:25.311+0530] {taskinstance.py:1304} INFO - Executing <Task(PythonOperator): extract_data> on 2023-03-02 00:00:00+00:00
[2023-03-17T05:05:25.320+0530] {standard_task_runner.py:55} INFO - Started process 5482 to run task
[2023-03-17T05:05:25.323+0530] {standard_task_runner.py:82} INFO - Running: ['airflow', 'tasks', 'run', 'nsdlfpi_and_rupee', 'extract_data', 'scheduled__2023-03-02T00:00:00+00:00', '--job-id', '4897', '--raw', '--subdir', 'DAGS_FOLDER/nsdl_and_rupee.py', '--cfg-path', '/tmp/tmpxewlfmir']
[2023-03-17T05:05:25.324+0530] {standard_task_runner.py:83} INFO - Job 4897: Subtask extract_data
[2023-03-17T05:05:25.384+0530] {task_command.py:389} INFO - Running <TaskInstance: nsdlfpi_and_rupee.extract_data scheduled__2023-03-02T00:00:00+00:00 [running]> on host DESKTOP-SQIOQPD.
[2023-03-17T05:05:25.629+0530] {taskinstance.py:1511} INFO - Exporting the following env vars:
AIRFLOW_CTX_DAG_EMAIL=nikheleshbhattacharyya@gmail.com
AIRFLOW_CTX_DAG_OWNER=airflow
AIRFLOW_CTX_DAG_ID=nsdlfpi_and_rupee
AIRFLOW_CTX_TASK_ID=extract_data
AIRFLOW_CTX_EXECUTION_DATE=2023-03-02T00:00:00+00:00
AIRFLOW_CTX_TRY_NUMBER=1
AIRFLOW_CTX_DAG_RUN_ID=scheduled__2023-03-02T00:00:00+00:00
[2023-03-17T05:07:10.588+0530] {taskinstance.py:1772} ERROR - Task failed with exception
Traceback (most recent call last):
  File "/usr/local/lib/python3.8/dist-packages/airflow/operators/python.py", line 175, in execute
    return_value = self.execute_callable()
  File "/usr/local/lib/python3.8/dist-packages/airflow/operators/python.py", line 192, in execute_callable
    return self.python_callable(*self.op_args, **self.op_kwargs)
  File "/root/airflow/dags/nsdl_and_rupee.py", line 135, in extract_nsdl_fpi
    driver = webdriver.Chrome('/usr/local/bin/chromedriver2',options=chrome_options)
  File "/usr/local/lib/python3.8/dist-packages/selenium/webdriver/chrome/webdriver.py", line 80, in __init__
    super().__init__(
  File "/usr/local/lib/python3.8/dist-packages/selenium/webdriver/chromium/webdriver.py", line 104, in __init__
    super().__init__(
  File "/usr/local/lib/python3.8/dist-packages/selenium/webdriver/remote/webdriver.py", line 286, in __init__
    self.start_session(capabilities, browser_profile)
  File "/usr/local/lib/python3.8/dist-packages/selenium/webdriver/remote/webdriver.py", line 378, in start_session
    response = self.execute(Command.NEW_SESSION, parameters)
  File "/usr/local/lib/python3.8/dist-packages/selenium/webdriver/remote/webdriver.py", line 440, in execute
    self.error_handler.check_response(response)
  File "/usr/local/lib/python3.8/dist-packages/selenium/webdriver/remote/errorhandler.py", line 245, in check_response
    raise exception_class(message, screen, stacktrace)
selenium.common.exceptions.WebDriverException: Message: chrome not reachable
Stacktrace:
#0 0x55ca09f5c303 <unknown>
#1 0x55ca09d30bbd <unknown>
#2 0x55ca09d1f696 <unknown>
#3 0x55ca09d5d77d <unknown>
#4 0x55ca09d5880e <unknown>
#5 0x55ca09d55330 <unknown>
#6 0x55ca09d964a6 <unknown>
#7 0x55ca09d8d753 <unknown>
#8 0x55ca09d60a14 <unknown>
#9 0x55ca09d61b7e <unknown>
#10 0x55ca09fab32e <unknown>
#11 0x55ca09faec0e <unknown>
#12 0x55ca09f91610 <unknown>
#13 0x55ca09fafc23 <unknown>
#14 0x55ca09f83545 <unknown>
#15 0x55ca09fd06a8 <unknown>
#16 0x55ca09fd0836 <unknown>
#17 0x55ca09febd13 <unknown>
#18 0x7fcb1f79d609 start_thread

[2023-03-17T05:07:10.901+0530] {taskinstance.py:1322} INFO - Marking task as UP_FOR_RETRY. dag_id=nsdlfpi_and_rupee, task_id=extract_data, execution_date=20230302T000000, start_date=20230316T233525, end_date=20230316T233710
[2023-03-17T05:07:11.232+0530] {standard_task_runner.py:100} ERROR - Failed to execute job 4897 for task extract_data (Message: chrome not reachable
Stacktrace:
#0 0x55ca09f5c303 <unknown>
#1 0x55ca09d30bbd <unknown>
#2 0x55ca09d1f696 <unknown>
#3 0x55ca09d5d77d <unknown>
#4 0x55ca09d5880e <unknown>
#5 0x55ca09d55330 <unknown>
#6 0x55ca09d964a6 <unknown>
#7 0x55ca09d8d753 <unknown>
#8 0x55ca09d60a14 <unknown>
#9 0x55ca09d61b7e <unknown>
#10 0x55ca09fab32e <unknown>
#11 0x55ca09faec0e <unknown>
#12 0x55ca09f91610 <unknown>
#13 0x55ca09fafc23 <unknown>
#14 0x55ca09f83545 <unknown>
#15 0x55ca09fd06a8 <unknown>
#16 0x55ca09fd0836 <unknown>
#17 0x55ca09febd13 <unknown>
#18 0x7fcb1f79d609 start_thread
; 5482)
[2023-03-17T05:07:11.310+0530] {local_task_job.py:159} INFO - Task exited with return code 1
[2023-03-17T05:07:11.508+0530] {taskinstance.py:2582} INFO - 0 downstream tasks scheduled from follow-on schedule check
