[2023-01-06T11:19:29.954+0530] {taskinstance.py:1087} INFO - Dependencies all met for <TaskInstance: Monthly.extract2 scheduled__2023-01-05T00:00:00+00:00 [queued]>
[2023-01-06T11:19:29.972+0530] {taskinstance.py:1087} INFO - Dependencies all met for <TaskInstance: Monthly.extract2 scheduled__2023-01-05T00:00:00+00:00 [queued]>
[2023-01-06T11:19:29.973+0530] {taskinstance.py:1283} INFO - 
--------------------------------------------------------------------------------
[2023-01-06T11:19:29.973+0530] {taskinstance.py:1284} INFO - Starting attempt 2 of 4
[2023-01-06T11:19:29.973+0530] {taskinstance.py:1285} INFO - 
--------------------------------------------------------------------------------
[2023-01-06T11:19:30.005+0530] {taskinstance.py:1304} INFO - Executing <Task(PythonOperator): extract2> on 2023-01-05 00:00:00+00:00
[2023-01-06T11:19:30.021+0530] {standard_task_runner.py:55} INFO - Started process 32758 to run task
[2023-01-06T11:19:30.022+0530] {standard_task_runner.py:82} INFO - Running: ['airflow', 'tasks', 'run', 'Monthly', 'extract2', 'scheduled__2023-01-05T00:00:00+00:00', '--job-id', '2897', '--raw', '--subdir', 'DAGS_FOLDER/Monthly.py', '--cfg-path', '/tmp/tmpb5w1bmcw']
[2023-01-06T11:19:30.024+0530] {standard_task_runner.py:83} INFO - Job 2897: Subtask extract2
[2023-01-06T11:19:30.156+0530] {task_command.py:389} INFO - Running <TaskInstance: Monthly.extract2 scheduled__2023-01-05T00:00:00+00:00 [running]> on host DESKTOP-SQIOQPD.
[2023-01-06T11:19:30.288+0530] {taskinstance.py:1511} INFO - Exporting the following env vars:
AIRFLOW_CTX_DAG_EMAIL=nikheleshbhattacharyya@gmail.com
AIRFLOW_CTX_DAG_OWNER=airflow
AIRFLOW_CTX_DAG_ID=Monthly
AIRFLOW_CTX_TASK_ID=extract2
AIRFLOW_CTX_EXECUTION_DATE=2023-01-05T00:00:00+00:00
AIRFLOW_CTX_TRY_NUMBER=2
AIRFLOW_CTX_DAG_RUN_ID=scheduled__2023-01-05T00:00:00+00:00
[2023-01-06T11:19:41.611+0530] {taskinstance.py:1772} ERROR - Task failed with exception
Traceback (most recent call last):
  File "/usr/local/lib/python3.8/dist-packages/airflow/operators/python.py", line 175, in execute
    return_value = self.execute_callable()
  File "/usr/local/lib/python3.8/dist-packages/airflow/operators/python.py", line 192, in execute_callable
    return self.python_callable(*self.op_args, **self.op_kwargs)
  File "/root/airflow/dags/Monthly.py", line 463, in extract2
    driver.get(url)
  File "/usr/local/lib/python3.8/dist-packages/selenium/webdriver/remote/webdriver.py", line 455, in get
    self.execute(Command.GET, {"url": url})
  File "/usr/local/lib/python3.8/dist-packages/selenium/webdriver/remote/webdriver.py", line 444, in execute
    self.error_handler.check_response(response)
  File "/usr/local/lib/python3.8/dist-packages/selenium/webdriver/remote/errorhandler.py", line 249, in check_response
    raise exception_class(message, screen, stacktrace)
selenium.common.exceptions.WebDriverException: Message: unknown error: net::ERR_NAME_NOT_RESOLVED
  (Session info: headless chrome=108.0.5359.124)
Stacktrace:
#0 0x56533a9502a3 <unknown>
#1 0x56533a70ef77 <unknown>
#2 0x56533a706e35 <unknown>
#3 0x56533a6f9f27 <unknown>
#4 0x56533a6fb2d9 <unknown>
#5 0x56533a6fa29e <unknown>
#6 0x56533a6f93d2 <unknown>
#7 0x56533a6f9225 <unknown>
#8 0x56533a6f7dc6 <unknown>
#9 0x56533a6f8244 <unknown>
#10 0x56533a710e88 <unknown>
#11 0x56533a783b05 <unknown>
#12 0x56533a76bb32 <unknown>
#13 0x56533a78347c <unknown>
#14 0x56533a76b903 <unknown>
#15 0x56533a73eece <unknown>
#16 0x56533a73ffde <unknown>
#17 0x56533a9a063e <unknown>
#18 0x56533a9a3b79 <unknown>
#19 0x56533a98689e <unknown>
#20 0x56533a9a4a83 <unknown>
#21 0x56533a979505 <unknown>
#22 0x56533a9c5ca8 <unknown>
#23 0x56533a9c5e36 <unknown>
#24 0x56533a9e1333 <unknown>
#25 0x7fd5b7c37609 start_thread

[2023-01-06T11:19:41.659+0530] {taskinstance.py:1322} INFO - Marking task as UP_FOR_RETRY. dag_id=Monthly, task_id=extract2, execution_date=20230105T000000, start_date=20230106T054929, end_date=20230106T054941
[2023-01-06T11:19:41.710+0530] {standard_task_runner.py:100} ERROR - Failed to execute job 2897 for task extract2 (Message: unknown error: net::ERR_NAME_NOT_RESOLVED
  (Session info: headless chrome=108.0.5359.124)
Stacktrace:
#0 0x56533a9502a3 <unknown>
#1 0x56533a70ef77 <unknown>
#2 0x56533a706e35 <unknown>
#3 0x56533a6f9f27 <unknown>
#4 0x56533a6fb2d9 <unknown>
#5 0x56533a6fa29e <unknown>
#6 0x56533a6f93d2 <unknown>
#7 0x56533a6f9225 <unknown>
#8 0x56533a6f7dc6 <unknown>
#9 0x56533a6f8244 <unknown>
#10 0x56533a710e88 <unknown>
#11 0x56533a783b05 <unknown>
#12 0x56533a76bb32 <unknown>
#13 0x56533a78347c <unknown>
#14 0x56533a76b903 <unknown>
#15 0x56533a73eece <unknown>
#16 0x56533a73ffde <unknown>
#17 0x56533a9a063e <unknown>
#18 0x56533a9a3b79 <unknown>
#19 0x56533a98689e <unknown>
#20 0x56533a9a4a83 <unknown>
#21 0x56533a979505 <unknown>
#22 0x56533a9c5ca8 <unknown>
#23 0x56533a9c5e36 <unknown>
#24 0x56533a9e1333 <unknown>
#25 0x7fd5b7c37609 start_thread
; 32758)
[2023-01-06T11:19:41.733+0530] {local_task_job.py:159} INFO - Task exited with return code 1
[2023-01-06T11:19:41.777+0530] {taskinstance.py:2582} INFO - 0 downstream tasks scheduled from follow-on schedule check
