[2023-02-01T21:03:58.061+0530] {taskinstance.py:1087} INFO - Dependencies all met for <TaskInstance: Monthly.load scheduled__2023-01-16T00:00:00+00:00 [queued]>
[2023-02-01T21:03:58.078+0530] {taskinstance.py:1087} INFO - Dependencies all met for <TaskInstance: Monthly.load scheduled__2023-01-16T00:00:00+00:00 [queued]>
[2023-02-01T21:03:58.079+0530] {taskinstance.py:1283} INFO - 
--------------------------------------------------------------------------------
[2023-02-01T21:03:58.079+0530] {taskinstance.py:1284} INFO - Starting attempt 1 of 4
[2023-02-01T21:03:58.079+0530] {taskinstance.py:1285} INFO - 
--------------------------------------------------------------------------------
[2023-02-01T21:03:58.110+0530] {taskinstance.py:1304} INFO - Executing <Task(PythonOperator): load> on 2023-01-16 00:00:00+00:00
[2023-02-01T21:03:58.121+0530] {standard_task_runner.py:55} INFO - Started process 1203 to run task
[2023-02-01T21:03:58.125+0530] {standard_task_runner.py:82} INFO - Running: ['airflow', 'tasks', 'run', 'Monthly', 'load', 'scheduled__2023-01-16T00:00:00+00:00', '--job-id', '3236', '--raw', '--subdir', 'DAGS_FOLDER/Monthly.py', '--cfg-path', '/tmp/tmpp1kwvyaj']
[2023-02-01T21:03:58.127+0530] {standard_task_runner.py:83} INFO - Job 3236: Subtask load
[2023-02-01T21:03:58.232+0530] {task_command.py:389} INFO - Running <TaskInstance: Monthly.load scheduled__2023-01-16T00:00:00+00:00 [running]> on host DESKTOP-SQIOQPD.
[2023-02-01T21:03:58.371+0530] {taskinstance.py:1511} INFO - Exporting the following env vars:
AIRFLOW_CTX_DAG_EMAIL=nikheleshbhattacharyya@gmail.com
AIRFLOW_CTX_DAG_OWNER=airflow
AIRFLOW_CTX_DAG_ID=Monthly
AIRFLOW_CTX_TASK_ID=load
AIRFLOW_CTX_EXECUTION_DATE=2023-01-16T00:00:00+00:00
AIRFLOW_CTX_TRY_NUMBER=1
AIRFLOW_CTX_DAG_RUN_ID=scheduled__2023-01-16T00:00:00+00:00
[2023-02-01T21:03:58.383+0530] {taskinstance.py:1772} ERROR - Task failed with exception
Traceback (most recent call last):
  File "/usr/local/lib/python3.8/dist-packages/airflow/operators/python.py", line 175, in execute
    return_value = self.execute_callable()
  File "/usr/local/lib/python3.8/dist-packages/airflow/operators/python.py", line 192, in execute_callable
    return self.python_callable(*self.op_args, **self.op_kwargs)
  File "/root/airflow/dags/Monthly.py", line 492, in load
    b4 = list(context['ti'].xcom_pull(task_ids='extract')[0])
TypeError: 'NoneType' object is not subscriptable
[2023-02-01T21:03:58.390+0530] {taskinstance.py:1322} INFO - Marking task as UP_FOR_RETRY. dag_id=Monthly, task_id=load, execution_date=20230116T000000, start_date=20230201T153358, end_date=20230201T153358
[2023-02-01T21:03:58.406+0530] {standard_task_runner.py:100} ERROR - Failed to execute job 3236 for task load ('NoneType' object is not subscriptable; 1203)
[2023-02-01T21:03:58.420+0530] {local_task_job.py:159} INFO - Task exited with return code 1
[2023-02-01T21:03:58.436+0530] {taskinstance.py:2582} INFO - 0 downstream tasks scheduled from follow-on schedule check
