[2023-02-13T20:58:49.374+0530] {taskinstance.py:1087} INFO - Dependencies all met for <TaskInstance: Monthly.extract scheduled__2023-02-03T00:00:00+00:00 [queued]>
[2023-02-13T20:58:49.384+0530] {taskinstance.py:1087} INFO - Dependencies all met for <TaskInstance: Monthly.extract scheduled__2023-02-03T00:00:00+00:00 [queued]>
[2023-02-13T20:58:49.384+0530] {taskinstance.py:1283} INFO - 
--------------------------------------------------------------------------------
[2023-02-13T20:58:49.384+0530] {taskinstance.py:1284} INFO - Starting attempt 2 of 4
[2023-02-13T20:58:49.384+0530] {taskinstance.py:1285} INFO - 
--------------------------------------------------------------------------------
[2023-02-13T20:58:49.399+0530] {taskinstance.py:1304} INFO - Executing <Task(PythonOperator): extract> on 2023-02-03 00:00:00+00:00
[2023-02-13T20:58:49.404+0530] {standard_task_runner.py:55} INFO - Started process 1136 to run task
[2023-02-13T20:58:49.408+0530] {standard_task_runner.py:82} INFO - Running: ['airflow', 'tasks', 'run', 'Monthly', 'extract', 'scheduled__2023-02-03T00:00:00+00:00', '--job-id', '3997', '--raw', '--subdir', 'DAGS_FOLDER/Monthly.py', '--cfg-path', '/tmp/tmpgv4r02_d']
[2023-02-13T20:58:49.410+0530] {standard_task_runner.py:83} INFO - Job 3997: Subtask extract
[2023-02-13T20:58:49.464+0530] {task_command.py:389} INFO - Running <TaskInstance: Monthly.extract scheduled__2023-02-03T00:00:00+00:00 [running]> on host DESKTOP-SQIOQPD.
[2023-02-13T20:58:49.528+0530] {taskinstance.py:1511} INFO - Exporting the following env vars:
AIRFLOW_CTX_DAG_EMAIL=nikheleshbhattacharyya@gmail.com
AIRFLOW_CTX_DAG_OWNER=airflow
AIRFLOW_CTX_DAG_ID=Monthly
AIRFLOW_CTX_TASK_ID=extract
AIRFLOW_CTX_EXECUTION_DATE=2023-02-03T00:00:00+00:00
AIRFLOW_CTX_TRY_NUMBER=2
AIRFLOW_CTX_DAG_RUN_ID=scheduled__2023-02-03T00:00:00+00:00
[2023-02-13T21:03:19.627+0530] {taskinstance.py:1772} ERROR - Task failed with exception
Traceback (most recent call last):
  File "/usr/local/lib/python3.8/dist-packages/airflow/operators/python.py", line 175, in execute
    return_value = self.execute_callable()
  File "/usr/local/lib/python3.8/dist-packages/airflow/operators/python.py", line 192, in execute_callable
    return self.python_callable(*self.op_args, **self.op_kwargs)
  File "/root/airflow/dags/Monthly.py", line 469, in extract
    driver.get(url)
  File "/usr/local/lib/python3.8/dist-packages/selenium/webdriver/remote/webdriver.py", line 449, in get
    self.execute(Command.GET, {"url": url})
  File "/usr/local/lib/python3.8/dist-packages/selenium/webdriver/remote/webdriver.py", line 440, in execute
    self.error_handler.check_response(response)
  File "/usr/local/lib/python3.8/dist-packages/selenium/webdriver/remote/errorhandler.py", line 245, in check_response
    raise exception_class(message, screen, stacktrace)
selenium.common.exceptions.WebDriverException: Message: unknown error: net::ERR_CONNECTION_RESET
  (Session info: headless chrome=109.0.5414.119)
Stacktrace:
#0 0x5605bded8303 <unknown>
#1 0x5605bdcacd37 <unknown>
#2 0x5605bdca4d85 <unknown>
#3 0x5605bdc97f87 <unknown>
#4 0x5605bdc994e9 <unknown>
#5 0x5605bdc982fe <unknown>
#6 0x5605bdc97432 <unknown>
#7 0x5605bdc97285 <unknown>
#8 0x5605bdc95c77 <unknown>
#9 0x5605bdc962a4 <unknown>
#10 0x5605bdcaec48 <unknown>
#11 0x5605bdd21f15 <unknown>
#12 0x5605bdd09982 <unknown>
#13 0x5605bdd2188c <unknown>
#14 0x5605bdd09753 <unknown>
#15 0x5605bdcdca14 <unknown>
#16 0x5605bdcddb7e <unknown>
#17 0x5605bdf2732e <unknown>
#18 0x5605bdf2ac0e <unknown>
#19 0x5605bdf0d610 <unknown>
#20 0x5605bdf2bc23 <unknown>
#21 0x5605bdeff545 <unknown>
#22 0x5605bdf4c6a8 <unknown>
#23 0x5605bdf4c836 <unknown>
#24 0x5605bdf67d13 <unknown>
#25 0x7ff361ba7609 start_thread

[2023-02-13T21:03:19.637+0530] {taskinstance.py:1322} INFO - Marking task as UP_FOR_RETRY. dag_id=Monthly, task_id=extract, execution_date=20230203T000000, start_date=20230213T152849, end_date=20230213T153319
[2023-02-13T21:03:19.651+0530] {standard_task_runner.py:100} ERROR - Failed to execute job 3997 for task extract (Message: unknown error: net::ERR_CONNECTION_RESET
  (Session info: headless chrome=109.0.5414.119)
Stacktrace:
#0 0x5605bded8303 <unknown>
#1 0x5605bdcacd37 <unknown>
#2 0x5605bdca4d85 <unknown>
#3 0x5605bdc97f87 <unknown>
#4 0x5605bdc994e9 <unknown>
#5 0x5605bdc982fe <unknown>
#6 0x5605bdc97432 <unknown>
#7 0x5605bdc97285 <unknown>
#8 0x5605bdc95c77 <unknown>
#9 0x5605bdc962a4 <unknown>
#10 0x5605bdcaec48 <unknown>
#11 0x5605bdd21f15 <unknown>
#12 0x5605bdd09982 <unknown>
#13 0x5605bdd2188c <unknown>
#14 0x5605bdd09753 <unknown>
#15 0x5605bdcdca14 <unknown>
#16 0x5605bdcddb7e <unknown>
#17 0x5605bdf2732e <unknown>
#18 0x5605bdf2ac0e <unknown>
#19 0x5605bdf0d610 <unknown>
#20 0x5605bdf2bc23 <unknown>
#21 0x5605bdeff545 <unknown>
#22 0x5605bdf4c6a8 <unknown>
#23 0x5605bdf4c836 <unknown>
#24 0x5605bdf67d13 <unknown>
#25 0x7ff361ba7609 start_thread
; 1136)
[2023-02-13T21:03:19.687+0530] {local_task_job.py:159} INFO - Task exited with return code 1
[2023-02-13T21:03:19.706+0530] {taskinstance.py:2582} INFO - 0 downstream tasks scheduled from follow-on schedule check
