[2023-01-13T19:09:06.365+0530] {taskinstance.py:1087} INFO - Dependencies all met for <TaskInstance: Monthly.load scheduled__2023-01-11T00:00:00+00:00 [queued]>
[2023-01-13T19:09:06.409+0530] {taskinstance.py:1087} INFO - Dependencies all met for <TaskInstance: Monthly.load scheduled__2023-01-11T00:00:00+00:00 [queued]>
[2023-01-13T19:09:06.410+0530] {taskinstance.py:1283} INFO - 
--------------------------------------------------------------------------------
[2023-01-13T19:09:06.410+0530] {taskinstance.py:1284} INFO - Starting attempt 1 of 4
[2023-01-13T19:09:06.410+0530] {taskinstance.py:1285} INFO - 
--------------------------------------------------------------------------------
[2023-01-13T19:09:06.494+0530] {taskinstance.py:1304} INFO - Executing <Task(PythonOperator): load> on 2023-01-11 00:00:00+00:00
[2023-01-13T19:09:06.500+0530] {standard_task_runner.py:55} INFO - Started process 13973 to run task
[2023-01-13T19:09:06.504+0530] {standard_task_runner.py:82} INFO - Running: ['airflow', 'tasks', 'run', 'Monthly', 'load', 'scheduled__2023-01-11T00:00:00+00:00', '--job-id', '3103', '--raw', '--subdir', 'DAGS_FOLDER/Monthly.py', '--cfg-path', '/tmp/tmp4esgihca']
[2023-01-13T19:09:06.505+0530] {standard_task_runner.py:83} INFO - Job 3103: Subtask load
[2023-01-13T19:09:06.684+0530] {task_command.py:389} INFO - Running <TaskInstance: Monthly.load scheduled__2023-01-11T00:00:00+00:00 [running]> on host DESKTOP-SQIOQPD.
[2023-01-13T19:09:06.928+0530] {taskinstance.py:1511} INFO - Exporting the following env vars:
AIRFLOW_CTX_DAG_EMAIL=nikheleshbhattacharyya@gmail.com
AIRFLOW_CTX_DAG_OWNER=airflow
AIRFLOW_CTX_DAG_ID=Monthly
AIRFLOW_CTX_TASK_ID=load
AIRFLOW_CTX_EXECUTION_DATE=2023-01-11T00:00:00+00:00
AIRFLOW_CTX_TRY_NUMBER=1
AIRFLOW_CTX_DAG_RUN_ID=scheduled__2023-01-11T00:00:00+00:00
[2023-01-13T19:09:06.959+0530] {taskinstance.py:1772} ERROR - Task failed with exception
Traceback (most recent call last):
  File "/usr/local/lib/python3.8/dist-packages/airflow/operators/python.py", line 175, in execute
    return_value = self.execute_callable()
  File "/usr/local/lib/python3.8/dist-packages/airflow/operators/python.py", line 192, in execute_callable
    return self.python_callable(*self.op_args, **self.op_kwargs)
  File "/root/airflow/dags/Monthly.py", line 492, in load
    b4 = list(context['ti'].xcom_pull(task_ids='extract')[0])
TypeError: 'NoneType' object is not subscriptable
[2023-01-13T19:09:06.976+0530] {taskinstance.py:1322} INFO - Marking task as UP_FOR_RETRY. dag_id=Monthly, task_id=load, execution_date=20230111T000000, start_date=20230113T133906, end_date=20230113T133906
[2023-01-13T19:09:07.045+0530] {standard_task_runner.py:100} ERROR - Failed to execute job 3103 for task load ('NoneType' object is not subscriptable; 13973)
[2023-01-13T19:09:07.079+0530] {local_task_job.py:159} INFO - Task exited with return code 1
[2023-01-13T19:09:07.116+0530] {taskinstance.py:2582} INFO - 0 downstream tasks scheduled from follow-on schedule check
