[2023-01-06T11:23:11.913+0530] {taskinstance.py:1087} INFO - Dependencies all met for <TaskInstance: Monthly.extract scheduled__2023-01-05T00:00:00+00:00 [queued]>
[2023-01-06T11:23:11.931+0530] {taskinstance.py:1087} INFO - Dependencies all met for <TaskInstance: Monthly.extract scheduled__2023-01-05T00:00:00+00:00 [queued]>
[2023-01-06T11:23:11.931+0530] {taskinstance.py:1283} INFO - 
--------------------------------------------------------------------------------
[2023-01-06T11:23:11.931+0530] {taskinstance.py:1284} INFO - Starting attempt 3 of 4
[2023-01-06T11:23:11.931+0530] {taskinstance.py:1285} INFO - 
--------------------------------------------------------------------------------
[2023-01-06T11:23:11.955+0530] {taskinstance.py:1304} INFO - Executing <Task(PythonOperator): extract> on 2023-01-05 00:00:00+00:00
[2023-01-06T11:23:11.964+0530] {standard_task_runner.py:55} INFO - Started process 1017 to run task
[2023-01-06T11:23:11.968+0530] {standard_task_runner.py:82} INFO - Running: ['airflow', 'tasks', 'run', 'Monthly', 'extract', 'scheduled__2023-01-05T00:00:00+00:00', '--job-id', '2907', '--raw', '--subdir', 'DAGS_FOLDER/Monthly.py', '--cfg-path', '/tmp/tmpijh0qh99']
[2023-01-06T11:23:11.970+0530] {standard_task_runner.py:83} INFO - Job 2907: Subtask extract
[2023-01-06T11:23:12.050+0530] {task_command.py:389} INFO - Running <TaskInstance: Monthly.extract scheduled__2023-01-05T00:00:00+00:00 [running]> on host DESKTOP-SQIOQPD.
[2023-01-06T11:23:12.155+0530] {taskinstance.py:1511} INFO - Exporting the following env vars:
AIRFLOW_CTX_DAG_EMAIL=nikheleshbhattacharyya@gmail.com
AIRFLOW_CTX_DAG_OWNER=airflow
AIRFLOW_CTX_DAG_ID=Monthly
AIRFLOW_CTX_TASK_ID=extract
AIRFLOW_CTX_EXECUTION_DATE=2023-01-05T00:00:00+00:00
AIRFLOW_CTX_TRY_NUMBER=3
AIRFLOW_CTX_DAG_RUN_ID=scheduled__2023-01-05T00:00:00+00:00
[2023-01-06T11:23:24.375+0530] {taskinstance.py:1772} ERROR - Task failed with exception
Traceback (most recent call last):
  File "/usr/local/lib/python3.8/dist-packages/airflow/operators/python.py", line 175, in execute
    return_value = self.execute_callable()
  File "/usr/local/lib/python3.8/dist-packages/airflow/operators/python.py", line 192, in execute_callable
    return self.python_callable(*self.op_args, **self.op_kwargs)
  File "/root/airflow/dags/Monthly.py", line 418, in extract
    driver.get(url)
  File "/usr/local/lib/python3.8/dist-packages/selenium/webdriver/remote/webdriver.py", line 455, in get
    self.execute(Command.GET, {"url": url})
  File "/usr/local/lib/python3.8/dist-packages/selenium/webdriver/remote/webdriver.py", line 444, in execute
    self.error_handler.check_response(response)
  File "/usr/local/lib/python3.8/dist-packages/selenium/webdriver/remote/errorhandler.py", line 249, in check_response
    raise exception_class(message, screen, stacktrace)
selenium.common.exceptions.WebDriverException: Message: unknown error: net::ERR_NAME_NOT_RESOLVED
  (Session info: headless chrome=108.0.5359.124)
Stacktrace:
#0 0x557017d2a2a3 <unknown>
#1 0x557017ae8f77 <unknown>
#2 0x557017ae0e35 <unknown>
#3 0x557017ad3f27 <unknown>
#4 0x557017ad52d9 <unknown>
#5 0x557017ad429e <unknown>
#6 0x557017ad33d2 <unknown>
#7 0x557017ad3225 <unknown>
#8 0x557017ad1dc6 <unknown>
#9 0x557017ad2244 <unknown>
#10 0x557017aeae88 <unknown>
#11 0x557017b5db05 <unknown>
#12 0x557017b45b32 <unknown>
#13 0x557017b5d47c <unknown>
#14 0x557017b45903 <unknown>
#15 0x557017b18ece <unknown>
#16 0x557017b19fde <unknown>
#17 0x557017d7a63e <unknown>
#18 0x557017d7db79 <unknown>
#19 0x557017d6089e <unknown>
#20 0x557017d7ea83 <unknown>
#21 0x557017d53505 <unknown>
#22 0x557017d9fca8 <unknown>
#23 0x557017d9fe36 <unknown>
#24 0x557017dbb333 <unknown>
#25 0x7fa2fb8a9609 start_thread

[2023-01-06T11:23:24.390+0530] {taskinstance.py:1322} INFO - Marking task as UP_FOR_RETRY. dag_id=Monthly, task_id=extract, execution_date=20230105T000000, start_date=20230106T055311, end_date=20230106T055324
[2023-01-06T11:23:24.414+0530] {standard_task_runner.py:100} ERROR - Failed to execute job 2907 for task extract (Message: unknown error: net::ERR_NAME_NOT_RESOLVED
  (Session info: headless chrome=108.0.5359.124)
Stacktrace:
#0 0x557017d2a2a3 <unknown>
#1 0x557017ae8f77 <unknown>
#2 0x557017ae0e35 <unknown>
#3 0x557017ad3f27 <unknown>
#4 0x557017ad52d9 <unknown>
#5 0x557017ad429e <unknown>
#6 0x557017ad33d2 <unknown>
#7 0x557017ad3225 <unknown>
#8 0x557017ad1dc6 <unknown>
#9 0x557017ad2244 <unknown>
#10 0x557017aeae88 <unknown>
#11 0x557017b5db05 <unknown>
#12 0x557017b45b32 <unknown>
#13 0x557017b5d47c <unknown>
#14 0x557017b45903 <unknown>
#15 0x557017b18ece <unknown>
#16 0x557017b19fde <unknown>
#17 0x557017d7a63e <unknown>
#18 0x557017d7db79 <unknown>
#19 0x557017d6089e <unknown>
#20 0x557017d7ea83 <unknown>
#21 0x557017d53505 <unknown>
#22 0x557017d9fca8 <unknown>
#23 0x557017d9fe36 <unknown>
#24 0x557017dbb333 <unknown>
#25 0x7fa2fb8a9609 start_thread
; 1017)
[2023-01-06T11:23:24.431+0530] {local_task_job.py:159} INFO - Task exited with return code 1
[2023-01-06T11:23:24.462+0530] {taskinstance.py:2582} INFO - 0 downstream tasks scheduled from follow-on schedule check
