[2023-01-07T11:41:22.770+0530] {taskinstance.py:1087} INFO - Dependencies all met for <TaskInstance: Monthly.extract scheduled__2023-01-06T00:00:00+00:00 [queued]>
[2023-01-07T11:41:22.799+0530] {taskinstance.py:1087} INFO - Dependencies all met for <TaskInstance: Monthly.extract scheduled__2023-01-06T00:00:00+00:00 [queued]>
[2023-01-07T11:41:22.799+0530] {taskinstance.py:1283} INFO - 
--------------------------------------------------------------------------------
[2023-01-07T11:41:22.800+0530] {taskinstance.py:1284} INFO - Starting attempt 4 of 4
[2023-01-07T11:41:22.800+0530] {taskinstance.py:1285} INFO - 
--------------------------------------------------------------------------------
[2023-01-07T11:41:22.834+0530] {taskinstance.py:1304} INFO - Executing <Task(PythonOperator): extract> on 2023-01-06 00:00:00+00:00
[2023-01-07T11:41:22.845+0530] {standard_task_runner.py:55} INFO - Started process 5885 to run task
[2023-01-07T11:41:22.851+0530] {standard_task_runner.py:82} INFO - Running: ['airflow', 'tasks', 'run', 'Monthly', 'extract', 'scheduled__2023-01-06T00:00:00+00:00', '--job-id', '2951', '--raw', '--subdir', 'DAGS_FOLDER/Monthly.py', '--cfg-path', '/tmp/tmpgj35cmez']
[2023-01-07T11:41:22.854+0530] {standard_task_runner.py:83} INFO - Job 2951: Subtask extract
[2023-01-07T11:41:22.958+0530] {task_command.py:389} INFO - Running <TaskInstance: Monthly.extract scheduled__2023-01-06T00:00:00+00:00 [running]> on host DESKTOP-SQIOQPD.
[2023-01-07T11:41:23.354+0530] {taskinstance.py:1511} INFO - Exporting the following env vars:
AIRFLOW_CTX_DAG_EMAIL=nikheleshbhattacharyya@gmail.com
AIRFLOW_CTX_DAG_OWNER=airflow
AIRFLOW_CTX_DAG_ID=Monthly
AIRFLOW_CTX_TASK_ID=extract
AIRFLOW_CTX_EXECUTION_DATE=2023-01-06T00:00:00+00:00
AIRFLOW_CTX_TRY_NUMBER=4
AIRFLOW_CTX_DAG_RUN_ID=scheduled__2023-01-06T00:00:00+00:00
[2023-01-07T11:52:38.902+0530] {taskinstance.py:1772} ERROR - Task failed with exception
Traceback (most recent call last):
  File "/usr/local/lib/python3.8/dist-packages/airflow/operators/python.py", line 175, in execute
    return_value = self.execute_callable()
  File "/usr/local/lib/python3.8/dist-packages/airflow/operators/python.py", line 192, in execute_callable
    return self.python_callable(*self.op_args, **self.op_kwargs)
  File "/root/airflow/dags/Monthly.py", line 416, in extract
    driver = webdriver.Chrome('/usr/local/bin/chromedriver',options=chrome_options)
  File "/usr/local/lib/python3.8/dist-packages/selenium/webdriver/chrome/webdriver.py", line 81, in __init__
    super().__init__(
  File "/usr/local/lib/python3.8/dist-packages/selenium/webdriver/chromium/webdriver.py", line 106, in __init__
    super().__init__(
  File "/usr/local/lib/python3.8/dist-packages/selenium/webdriver/remote/webdriver.py", line 288, in __init__
    self.start_session(capabilities, browser_profile)
  File "/usr/local/lib/python3.8/dist-packages/selenium/webdriver/remote/webdriver.py", line 381, in start_session
    response = self.execute(Command.NEW_SESSION, parameters)
  File "/usr/local/lib/python3.8/dist-packages/selenium/webdriver/remote/webdriver.py", line 444, in execute
    self.error_handler.check_response(response)
  File "/usr/local/lib/python3.8/dist-packages/selenium/webdriver/remote/errorhandler.py", line 249, in check_response
    raise exception_class(message, screen, stacktrace)
selenium.common.exceptions.TimeoutException: Message: timeout: Timed out receiving message from renderer: 600.000
  (Session info: headless chrome=108.0.5359.124)
Stacktrace:
#0 0x5648be3c82a3 <unknown>
#1 0x5648be186f77 <unknown>
#2 0x5648be1714e9 <unknown>
#3 0x5648be171225 <unknown>
#4 0x5648be16fdc6 <unknown>
#5 0x5648be170244 <unknown>
#6 0x5648be16ec21 <unknown>
#7 0x5648be17e50c <unknown>
#8 0x5648be16e704 <unknown>
#9 0x5648be170ecc <unknown>
#10 0x5648be16fdc6 <unknown>
#11 0x5648be170244 <unknown>
#12 0x5648be16ec21 <unknown>
#13 0x5648be17b4f0 <unknown>
#14 0x5648be16e704 <unknown>
#15 0x5648be170ecc <unknown>
#16 0x5648be16fdc6 <unknown>
#17 0x5648be170244 <unknown>
#18 0x5648be16ec21 <unknown>
#19 0x5648be176eef <unknown>
#20 0x5648be16e704 <unknown>
#21 0x5648be170ecc <unknown>
#22 0x5648be16fdc6 <unknown>
#23 0x5648be170244 <unknown>
#24 0x5648be16ec21 <unknown>
#25 0x5648be1678f2 <unknown>
#26 0x5648be16e704 <unknown>
#27 0x5648be16dd1a <unknown>
#28 0x5648be16d855 <unknown>
#29 0x5648be1887a2 <unknown>
#30 0x5648be16193f <unknown>
#31 0x5648be160875 <unknown>
#32 0x5648be1ec20f <unknown>
#33 0x5648be1eba5f <unknown>
#34 0x5648be1e3903 <unknown>
#35 0x5648be1b6ece <unknown>
#36 0x5648be1b7fde <unknown>
#37 0x5648be41863e <unknown>
#38 0x5648be41bb79 <unknown>
#39 0x5648be3fe89e <unknown>
#40 0x5648be41ca83 <unknown>
#41 0x5648be3f1505 <unknown>
#42 0x5648be43dca8 <unknown>
#43 0x5648be43de36 <unknown>
#44 0x5648be459333 <unknown>
#45 0x7f104b128609 start_thread

[2023-01-07T11:52:39.025+0530] {taskinstance.py:1322} INFO - Marking task as FAILED. dag_id=Monthly, task_id=extract, execution_date=20230106T000000, start_date=20230107T061122, end_date=20230107T062239
[2023-01-07T11:52:39.157+0530] {logging_mixin.py:137} WARNING - /usr/local/lib/python3.8/dist-packages/airflow/utils/email.py:120 RemovedInAirflow3Warning: Fetching SMTP credentials from configuration variables will be deprecated in a future release. Please set credentials using a connection instead.
[2023-01-07T11:52:39.158+0530] {configuration.py:635} WARNING - section/key [smtp/smtp_user] not found in config
[2023-01-07T11:52:39.158+0530] {email.py:229} INFO - Email alerting: attempt 1
[2023-01-07T11:52:39.172+0530] {configuration.py:635} WARNING - section/key [smtp/smtp_user] not found in config
[2023-01-07T11:52:39.173+0530] {email.py:229} INFO - Email alerting: attempt 1
[2023-01-07T11:52:39.174+0530] {taskinstance.py:1835} ERROR - Failed to send email to: ['nikheleshbhattacharyya@gmail.com']
Traceback (most recent call last):
  File "/usr/local/lib/python3.8/dist-packages/airflow/models/taskinstance.py", line 1378, in _run_raw_task
    self._execute_task_with_callbacks(context, test_mode)
  File "/usr/local/lib/python3.8/dist-packages/airflow/models/taskinstance.py", line 1524, in _execute_task_with_callbacks
    result = self._execute_task(context, task_orig)
  File "/usr/local/lib/python3.8/dist-packages/airflow/models/taskinstance.py", line 1585, in _execute_task
    result = execute_callable(context=context)
  File "/usr/local/lib/python3.8/dist-packages/airflow/operators/python.py", line 175, in execute
    return_value = self.execute_callable()
  File "/usr/local/lib/python3.8/dist-packages/airflow/operators/python.py", line 192, in execute_callable
    return self.python_callable(*self.op_args, **self.op_kwargs)
  File "/root/airflow/dags/Monthly.py", line 416, in extract
    driver = webdriver.Chrome('/usr/local/bin/chromedriver',options=chrome_options)
  File "/usr/local/lib/python3.8/dist-packages/selenium/webdriver/chrome/webdriver.py", line 81, in __init__
    super().__init__(
  File "/usr/local/lib/python3.8/dist-packages/selenium/webdriver/chromium/webdriver.py", line 106, in __init__
    super().__init__(
  File "/usr/local/lib/python3.8/dist-packages/selenium/webdriver/remote/webdriver.py", line 288, in __init__
    self.start_session(capabilities, browser_profile)
  File "/usr/local/lib/python3.8/dist-packages/selenium/webdriver/remote/webdriver.py", line 381, in start_session
    response = self.execute(Command.NEW_SESSION, parameters)
  File "/usr/local/lib/python3.8/dist-packages/selenium/webdriver/remote/webdriver.py", line 444, in execute
    self.error_handler.check_response(response)
  File "/usr/local/lib/python3.8/dist-packages/selenium/webdriver/remote/errorhandler.py", line 249, in check_response
    raise exception_class(message, screen, stacktrace)
selenium.common.exceptions.TimeoutException: Message: timeout: Timed out receiving message from renderer: 600.000
  (Session info: headless chrome=108.0.5359.124)
Stacktrace:
#0 0x5648be3c82a3 <unknown>
#1 0x5648be186f77 <unknown>
#2 0x5648be1714e9 <unknown>
#3 0x5648be171225 <unknown>
#4 0x5648be16fdc6 <unknown>
#5 0x5648be170244 <unknown>
#6 0x5648be16ec21 <unknown>
#7 0x5648be17e50c <unknown>
#8 0x5648be16e704 <unknown>
#9 0x5648be170ecc <unknown>
#10 0x5648be16fdc6 <unknown>
#11 0x5648be170244 <unknown>
#12 0x5648be16ec21 <unknown>
#13 0x5648be17b4f0 <unknown>
#14 0x5648be16e704 <unknown>
#15 0x5648be170ecc <unknown>
#16 0x5648be16fdc6 <unknown>
#17 0x5648be170244 <unknown>
#18 0x5648be16ec21 <unknown>
#19 0x5648be176eef <unknown>
#20 0x5648be16e704 <unknown>
#21 0x5648be170ecc <unknown>
#22 0x5648be16fdc6 <unknown>
#23 0x5648be170244 <unknown>
#24 0x5648be16ec21 <unknown>
#25 0x5648be1678f2 <unknown>
#26 0x5648be16e704 <unknown>
#27 0x5648be16dd1a <unknown>
#28 0x5648be16d855 <unknown>
#29 0x5648be1887a2 <unknown>
#30 0x5648be16193f <unknown>
#31 0x5648be160875 <unknown>
#32 0x5648be1ec20f <unknown>
#33 0x5648be1eba5f <unknown>
#34 0x5648be1e3903 <unknown>
#35 0x5648be1b6ece <unknown>
#36 0x5648be1b7fde <unknown>
#37 0x5648be41863e <unknown>
#38 0x5648be41bb79 <unknown>
#39 0x5648be3fe89e <unknown>
#40 0x5648be41ca83 <unknown>
#41 0x5648be3f1505 <unknown>
#42 0x5648be43dca8 <unknown>
#43 0x5648be43de36 <unknown>
#44 0x5648be459333 <unknown>
#45 0x7f104b128609 start_thread


During handling of the above exception, another exception occurred:

Traceback (most recent call last):
  File "/usr/local/lib/python3.8/dist-packages/airflow/models/taskinstance.py", line 2235, in email_alert
    send_email(task.email, subject, html_content)
  File "/usr/local/lib/python3.8/dist-packages/airflow/utils/email.py", line 59, in send_email
    return backend(
  File "/usr/local/lib/python3.8/dist-packages/airflow/utils/email.py", line 120, in send_email_smtp
    send_mime_email(e_from=mail_from, e_to=recipients, mime_msg=msg, conn_id=conn_id, dryrun=dryrun)
  File "/usr/local/lib/python3.8/dist-packages/airflow/utils/email.py", line 231, in send_mime_email
    smtp_conn = _get_smtp_connection(smtp_host, smtp_port, smtp_timeout, smtp_ssl)
  File "/usr/local/lib/python3.8/dist-packages/airflow/utils/email.py", line 265, in _get_smtp_connection
    else smtplib.SMTP(host=host, port=port, timeout=timeout)
  File "/usr/lib/python3.8/smtplib.py", line 255, in __init__
    (code, msg) = self.connect(host, port)
  File "/usr/lib/python3.8/smtplib.py", line 339, in connect
    self.sock = self._get_socket(host, port, self.timeout)
  File "/usr/lib/python3.8/smtplib.py", line 310, in _get_socket
    return socket.create_connection((host, port), timeout,
  File "/usr/lib/python3.8/socket.py", line 808, in create_connection
    raise err
  File "/usr/lib/python3.8/socket.py", line 796, in create_connection
    sock.connect(sa)
ConnectionRefusedError: [Errno 111] Connection refused

During handling of the above exception, another exception occurred:

Traceback (most recent call last):
  File "/usr/local/lib/python3.8/dist-packages/airflow/models/taskinstance.py", line 1833, in handle_failure
    self.email_alert(error, task)
  File "/usr/local/lib/python3.8/dist-packages/airflow/models/taskinstance.py", line 2237, in email_alert
    send_email(task.email, subject, html_content_err)
  File "/usr/local/lib/python3.8/dist-packages/airflow/utils/email.py", line 59, in send_email
    return backend(
  File "/usr/local/lib/python3.8/dist-packages/airflow/utils/email.py", line 120, in send_email_smtp
    send_mime_email(e_from=mail_from, e_to=recipients, mime_msg=msg, conn_id=conn_id, dryrun=dryrun)
  File "/usr/local/lib/python3.8/dist-packages/airflow/utils/email.py", line 231, in send_mime_email
    smtp_conn = _get_smtp_connection(smtp_host, smtp_port, smtp_timeout, smtp_ssl)
  File "/usr/local/lib/python3.8/dist-packages/airflow/utils/email.py", line 265, in _get_smtp_connection
    else smtplib.SMTP(host=host, port=port, timeout=timeout)
  File "/usr/lib/python3.8/smtplib.py", line 255, in __init__
    (code, msg) = self.connect(host, port)
  File "/usr/lib/python3.8/smtplib.py", line 339, in connect
    self.sock = self._get_socket(host, port, self.timeout)
  File "/usr/lib/python3.8/smtplib.py", line 310, in _get_socket
    return socket.create_connection((host, port), timeout,
  File "/usr/lib/python3.8/socket.py", line 808, in create_connection
    raise err
  File "/usr/lib/python3.8/socket.py", line 796, in create_connection
    sock.connect(sa)
ConnectionRefusedError: [Errno 111] Connection refused
[2023-01-07T11:52:39.267+0530] {standard_task_runner.py:100} ERROR - Failed to execute job 2951 for task extract (Message: timeout: Timed out receiving message from renderer: 600.000
  (Session info: headless chrome=108.0.5359.124)
Stacktrace:
#0 0x5648be3c82a3 <unknown>
#1 0x5648be186f77 <unknown>
#2 0x5648be1714e9 <unknown>
#3 0x5648be171225 <unknown>
#4 0x5648be16fdc6 <unknown>
#5 0x5648be170244 <unknown>
#6 0x5648be16ec21 <unknown>
#7 0x5648be17e50c <unknown>
#8 0x5648be16e704 <unknown>
#9 0x5648be170ecc <unknown>
#10 0x5648be16fdc6 <unknown>
#11 0x5648be170244 <unknown>
#12 0x5648be16ec21 <unknown>
#13 0x5648be17b4f0 <unknown>
#14 0x5648be16e704 <unknown>
#15 0x5648be170ecc <unknown>
#16 0x5648be16fdc6 <unknown>
#17 0x5648be170244 <unknown>
#18 0x5648be16ec21 <unknown>
#19 0x5648be176eef <unknown>
#20 0x5648be16e704 <unknown>
#21 0x5648be170ecc <unknown>
#22 0x5648be16fdc6 <unknown>
#23 0x5648be170244 <unknown>
#24 0x5648be16ec21 <unknown>
#25 0x5648be1678f2 <unknown>
#26 0x5648be16e704 <unknown>
#27 0x5648be16dd1a <unknown>
#28 0x5648be16d855 <unknown>
#29 0x5648be1887a2 <unknown>
#30 0x5648be16193f <unknown>
#31 0x5648be160875 <unknown>
#32 0x5648be1ec20f <unknown>
#33 0x5648be1eba5f <unknown>
#34 0x5648be1e3903 <unknown>
#35 0x5648be1b6ece <unknown>
#36 0x5648be1b7fde <unknown>
#37 0x5648be41863e <unknown>
#38 0x5648be41bb79 <unknown>
#39 0x5648be3fe89e <unknown>
#40 0x5648be41ca83 <unknown>
#41 0x5648be3f1505 <unknown>
#42 0x5648be43dca8 <unknown>
#43 0x5648be43de36 <unknown>
#44 0x5648be459333 <unknown>
#45 0x7f104b128609 start_thread
; 5885)
[2023-01-07T11:52:39.359+0530] {local_task_job.py:159} INFO - Task exited with return code 1
[2023-01-07T11:52:39.448+0530] {taskinstance.py:2582} INFO - 0 downstream tasks scheduled from follow-on schedule check
