[2023-02-02T05:28:08.477+0530] {taskinstance.py:1087} INFO - Dependencies all met for <TaskInstance: NSE_Open_Interest.extract scheduled__2023-01-26T00:00:00+00:00 [queued]>
[2023-02-02T05:28:08.484+0530] {taskinstance.py:1087} INFO - Dependencies all met for <TaskInstance: NSE_Open_Interest.extract scheduled__2023-01-26T00:00:00+00:00 [queued]>
[2023-02-02T05:28:08.485+0530] {taskinstance.py:1283} INFO - 
--------------------------------------------------------------------------------
[2023-02-02T05:28:08.485+0530] {taskinstance.py:1284} INFO - Starting attempt 4 of 4
[2023-02-02T05:28:08.485+0530] {taskinstance.py:1285} INFO - 
--------------------------------------------------------------------------------
[2023-02-02T05:28:08.501+0530] {taskinstance.py:1304} INFO - Executing <Task(PythonOperator): extract> on 2023-01-26 00:00:00+00:00
[2023-02-02T05:28:08.506+0530] {standard_task_runner.py:55} INFO - Started process 6134 to run task
[2023-02-02T05:28:08.509+0530] {standard_task_runner.py:82} INFO - Running: ['airflow', 'tasks', 'run', 'NSE_Open_Interest', 'extract', 'scheduled__2023-01-26T00:00:00+00:00', '--job-id', '3575', '--raw', '--subdir', 'DAGS_FOLDER/NSE_Open_Interest.py', '--cfg-path', '/tmp/tmprvqiem12']
[2023-02-02T05:28:08.510+0530] {standard_task_runner.py:83} INFO - Job 3575: Subtask extract
[2023-02-02T05:28:08.563+0530] {task_command.py:389} INFO - Running <TaskInstance: NSE_Open_Interest.extract scheduled__2023-01-26T00:00:00+00:00 [running]> on host DESKTOP-SQIOQPD.
[2023-02-02T05:28:08.629+0530] {taskinstance.py:1511} INFO - Exporting the following env vars:
AIRFLOW_CTX_DAG_EMAIL=nikheleshbhattacharyya@gmail.com
AIRFLOW_CTX_DAG_OWNER=airflow
AIRFLOW_CTX_DAG_ID=NSE_Open_Interest
AIRFLOW_CTX_TASK_ID=extract
AIRFLOW_CTX_EXECUTION_DATE=2023-01-26T00:00:00+00:00
AIRFLOW_CTX_TRY_NUMBER=4
AIRFLOW_CTX_DAG_RUN_ID=scheduled__2023-01-26T00:00:00+00:00
[2023-02-02T05:28:08.630+0530] {logging_mixin.py:137} INFO - 2020-02-14 00:00:00
[2023-02-02T05:28:08.670+0530] {logging_mixin.py:137} INFO - 2020-02-15 00:00:00
[2023-02-02T05:28:08.706+0530] {logging_mixin.py:137} INFO - 2020-02-16 00:00:00
[2023-02-02T05:28:11.802+0530] {logging_mixin.py:137} INFO - 2020-02-17 00:00:00
[2023-02-02T05:28:11.891+0530] {logging_mixin.py:137} INFO - 2020-02-18 00:00:00
[2023-02-02T05:28:11.926+0530] {logging_mixin.py:137} INFO - 2020-02-19 00:00:00
[2023-02-02T05:28:12.326+0530] {logging_mixin.py:137} INFO - 2020-02-20 00:00:00
[2023-02-02T05:28:12.443+0530] {logging_mixin.py:137} INFO - 2020-02-21 00:00:00
[2023-02-02T05:28:15.532+0530] {logging_mixin.py:137} INFO - 2020-02-22 00:00:00
[2023-02-02T05:28:15.568+0530] {logging_mixin.py:137} INFO - 2020-02-23 00:00:00
[2023-02-02T05:28:15.824+0530] {logging_mixin.py:137} INFO - 2020-02-24 00:00:00
[2023-02-02T05:28:15.932+0530] {logging_mixin.py:137} INFO - 2020-02-25 00:00:00
[2023-02-02T05:28:16.136+0530] {taskinstance.py:1772} ERROR - Task failed with exception
Traceback (most recent call last):
  File "/usr/local/lib/python3.8/dist-packages/airflow/operators/python.py", line 175, in execute
    return_value = self.execute_callable()
  File "/usr/local/lib/python3.8/dist-packages/airflow/operators/python.py", line 192, in execute_callable
    return self.python_callable(*self.op_args, **self.op_kwargs)
  File "/root/airflow/dags/NSE_Open_Interest.py", line 83, in extract
    dd,values = get_data(date)
TypeError: cannot unpack non-iterable int object
[2023-02-02T05:28:16.142+0530] {taskinstance.py:1322} INFO - Marking task as FAILED. dag_id=NSE_Open_Interest, task_id=extract, execution_date=20230126T000000, start_date=20230201T235808, end_date=20230201T235816
[2023-02-02T05:28:16.165+0530] {logging_mixin.py:137} WARNING - /usr/local/lib/python3.8/dist-packages/airflow/utils/email.py:120 RemovedInAirflow3Warning: Fetching SMTP credentials from configuration variables will be deprecated in a future release. Please set credentials using a connection instead.
[2023-02-02T05:28:16.165+0530] {configuration.py:635} WARNING - section/key [smtp/smtp_user] not found in config
[2023-02-02T05:28:16.165+0530] {email.py:229} INFO - Email alerting: attempt 1
[2023-02-02T05:28:16.168+0530] {configuration.py:635} WARNING - section/key [smtp/smtp_user] not found in config
[2023-02-02T05:28:16.168+0530] {email.py:229} INFO - Email alerting: attempt 1
[2023-02-02T05:28:16.168+0530] {taskinstance.py:1835} ERROR - Failed to send email to: ['nikheleshbhattacharyya@gmail.com']
Traceback (most recent call last):
  File "/usr/local/lib/python3.8/dist-packages/airflow/models/taskinstance.py", line 1378, in _run_raw_task
    self._execute_task_with_callbacks(context, test_mode)
  File "/usr/local/lib/python3.8/dist-packages/airflow/models/taskinstance.py", line 1524, in _execute_task_with_callbacks
    result = self._execute_task(context, task_orig)
  File "/usr/local/lib/python3.8/dist-packages/airflow/models/taskinstance.py", line 1585, in _execute_task
    result = execute_callable(context=context)
  File "/usr/local/lib/python3.8/dist-packages/airflow/operators/python.py", line 175, in execute
    return_value = self.execute_callable()
  File "/usr/local/lib/python3.8/dist-packages/airflow/operators/python.py", line 192, in execute_callable
    return self.python_callable(*self.op_args, **self.op_kwargs)
  File "/root/airflow/dags/NSE_Open_Interest.py", line 83, in extract
    dd,values = get_data(date)
TypeError: cannot unpack non-iterable int object

During handling of the above exception, another exception occurred:

Traceback (most recent call last):
  File "/usr/local/lib/python3.8/dist-packages/airflow/models/taskinstance.py", line 2235, in email_alert
    send_email(task.email, subject, html_content)
  File "/usr/local/lib/python3.8/dist-packages/airflow/utils/email.py", line 59, in send_email
    return backend(
  File "/usr/local/lib/python3.8/dist-packages/airflow/utils/email.py", line 120, in send_email_smtp
    send_mime_email(e_from=mail_from, e_to=recipients, mime_msg=msg, conn_id=conn_id, dryrun=dryrun)
  File "/usr/local/lib/python3.8/dist-packages/airflow/utils/email.py", line 231, in send_mime_email
    smtp_conn = _get_smtp_connection(smtp_host, smtp_port, smtp_timeout, smtp_ssl)
  File "/usr/local/lib/python3.8/dist-packages/airflow/utils/email.py", line 265, in _get_smtp_connection
    else smtplib.SMTP(host=host, port=port, timeout=timeout)
  File "/usr/lib/python3.8/smtplib.py", line 255, in __init__
    (code, msg) = self.connect(host, port)
  File "/usr/lib/python3.8/smtplib.py", line 339, in connect
    self.sock = self._get_socket(host, port, self.timeout)
  File "/usr/lib/python3.8/smtplib.py", line 310, in _get_socket
    return socket.create_connection((host, port), timeout,
  File "/usr/lib/python3.8/socket.py", line 808, in create_connection
    raise err
  File "/usr/lib/python3.8/socket.py", line 796, in create_connection
    sock.connect(sa)
ConnectionRefusedError: [Errno 111] Connection refused

During handling of the above exception, another exception occurred:

Traceback (most recent call last):
  File "/usr/local/lib/python3.8/dist-packages/airflow/models/taskinstance.py", line 1833, in handle_failure
    self.email_alert(error, task)
  File "/usr/local/lib/python3.8/dist-packages/airflow/models/taskinstance.py", line 2237, in email_alert
    send_email(task.email, subject, html_content_err)
  File "/usr/local/lib/python3.8/dist-packages/airflow/utils/email.py", line 59, in send_email
    return backend(
  File "/usr/local/lib/python3.8/dist-packages/airflow/utils/email.py", line 120, in send_email_smtp
    send_mime_email(e_from=mail_from, e_to=recipients, mime_msg=msg, conn_id=conn_id, dryrun=dryrun)
  File "/usr/local/lib/python3.8/dist-packages/airflow/utils/email.py", line 231, in send_mime_email
    smtp_conn = _get_smtp_connection(smtp_host, smtp_port, smtp_timeout, smtp_ssl)
  File "/usr/local/lib/python3.8/dist-packages/airflow/utils/email.py", line 265, in _get_smtp_connection
    else smtplib.SMTP(host=host, port=port, timeout=timeout)
  File "/usr/lib/python3.8/smtplib.py", line 255, in __init__
    (code, msg) = self.connect(host, port)
  File "/usr/lib/python3.8/smtplib.py", line 339, in connect
    self.sock = self._get_socket(host, port, self.timeout)
  File "/usr/lib/python3.8/smtplib.py", line 310, in _get_socket
    return socket.create_connection((host, port), timeout,
  File "/usr/lib/python3.8/socket.py", line 808, in create_connection
    raise err
  File "/usr/lib/python3.8/socket.py", line 796, in create_connection
    sock.connect(sa)
ConnectionRefusedError: [Errno 111] Connection refused
[2023-02-02T05:28:16.179+0530] {standard_task_runner.py:100} ERROR - Failed to execute job 3575 for task extract (cannot unpack non-iterable int object; 6134)
[2023-02-02T05:28:16.198+0530] {local_task_job.py:159} INFO - Task exited with return code 1
[2023-02-02T05:28:16.217+0530] {taskinstance.py:2582} INFO - 0 downstream tasks scheduled from follow-on schedule check
