[2023-01-06T11:21:47.823+0530] {taskinstance.py:1087} INFO - Dependencies all met for <TaskInstance: Monthly.extract2 scheduled__2023-01-05T00:00:00+00:00 [queued]>
[2023-01-06T11:21:47.840+0530] {taskinstance.py:1087} INFO - Dependencies all met for <TaskInstance: Monthly.extract2 scheduled__2023-01-05T00:00:00+00:00 [queued]>
[2023-01-06T11:21:47.840+0530] {taskinstance.py:1283} INFO - 
--------------------------------------------------------------------------------
[2023-01-06T11:21:47.840+0530] {taskinstance.py:1284} INFO - Starting attempt 3 of 4
[2023-01-06T11:21:47.840+0530] {taskinstance.py:1285} INFO - 
--------------------------------------------------------------------------------
[2023-01-06T11:21:47.871+0530] {taskinstance.py:1304} INFO - Executing <Task(PythonOperator): extract2> on 2023-01-05 00:00:00+00:00
[2023-01-06T11:21:47.881+0530] {standard_task_runner.py:55} INFO - Started process 709 to run task
[2023-01-06T11:21:47.886+0530] {standard_task_runner.py:82} INFO - Running: ['airflow', 'tasks', 'run', 'Monthly', 'extract2', 'scheduled__2023-01-05T00:00:00+00:00', '--job-id', '2903', '--raw', '--subdir', 'DAGS_FOLDER/Monthly.py', '--cfg-path', '/tmp/tmp5wta0nru']
[2023-01-06T11:21:47.888+0530] {standard_task_runner.py:83} INFO - Job 2903: Subtask extract2
[2023-01-06T11:21:48.000+0530] {task_command.py:389} INFO - Running <TaskInstance: Monthly.extract2 scheduled__2023-01-05T00:00:00+00:00 [running]> on host DESKTOP-SQIOQPD.
[2023-01-06T11:21:48.158+0530] {taskinstance.py:1511} INFO - Exporting the following env vars:
AIRFLOW_CTX_DAG_EMAIL=nikheleshbhattacharyya@gmail.com
AIRFLOW_CTX_DAG_OWNER=airflow
AIRFLOW_CTX_DAG_ID=Monthly
AIRFLOW_CTX_TASK_ID=extract2
AIRFLOW_CTX_EXECUTION_DATE=2023-01-05T00:00:00+00:00
AIRFLOW_CTX_TRY_NUMBER=3
AIRFLOW_CTX_DAG_RUN_ID=scheduled__2023-01-05T00:00:00+00:00
[2023-01-06T11:22:00.223+0530] {taskinstance.py:1772} ERROR - Task failed with exception
Traceback (most recent call last):
  File "/usr/local/lib/python3.8/dist-packages/airflow/operators/python.py", line 175, in execute
    return_value = self.execute_callable()
  File "/usr/local/lib/python3.8/dist-packages/airflow/operators/python.py", line 192, in execute_callable
    return self.python_callable(*self.op_args, **self.op_kwargs)
  File "/root/airflow/dags/Monthly.py", line 463, in extract2
    driver.get(url)
  File "/usr/local/lib/python3.8/dist-packages/selenium/webdriver/remote/webdriver.py", line 455, in get
    self.execute(Command.GET, {"url": url})
  File "/usr/local/lib/python3.8/dist-packages/selenium/webdriver/remote/webdriver.py", line 444, in execute
    self.error_handler.check_response(response)
  File "/usr/local/lib/python3.8/dist-packages/selenium/webdriver/remote/errorhandler.py", line 249, in check_response
    raise exception_class(message, screen, stacktrace)
selenium.common.exceptions.WebDriverException: Message: unknown error: net::ERR_NAME_NOT_RESOLVED
  (Session info: headless chrome=108.0.5359.124)
Stacktrace:
#0 0x55c2d676c2a3 <unknown>
#1 0x55c2d652af77 <unknown>
#2 0x55c2d6522e35 <unknown>
#3 0x55c2d6515f27 <unknown>
#4 0x55c2d65172d9 <unknown>
#5 0x55c2d651629e <unknown>
#6 0x55c2d65153d2 <unknown>
#7 0x55c2d6515225 <unknown>
#8 0x55c2d6513dc6 <unknown>
#9 0x55c2d6514244 <unknown>
#10 0x55c2d652ce88 <unknown>
#11 0x55c2d659fb05 <unknown>
#12 0x55c2d6587b32 <unknown>
#13 0x55c2d659f47c <unknown>
#14 0x55c2d6587903 <unknown>
#15 0x55c2d655aece <unknown>
#16 0x55c2d655bfde <unknown>
#17 0x55c2d67bc63e <unknown>
#18 0x55c2d67bfb79 <unknown>
#19 0x55c2d67a289e <unknown>
#20 0x55c2d67c0a83 <unknown>
#21 0x55c2d6795505 <unknown>
#22 0x55c2d67e1ca8 <unknown>
#23 0x55c2d67e1e36 <unknown>
#24 0x55c2d67fd333 <unknown>
#25 0x7fb4c82cf609 start_thread

[2023-01-06T11:22:00.254+0530] {taskinstance.py:1322} INFO - Marking task as UP_FOR_RETRY. dag_id=Monthly, task_id=extract2, execution_date=20230105T000000, start_date=20230106T055147, end_date=20230106T055200
[2023-01-06T11:22:00.295+0530] {standard_task_runner.py:100} ERROR - Failed to execute job 2903 for task extract2 (Message: unknown error: net::ERR_NAME_NOT_RESOLVED
  (Session info: headless chrome=108.0.5359.124)
Stacktrace:
#0 0x55c2d676c2a3 <unknown>
#1 0x55c2d652af77 <unknown>
#2 0x55c2d6522e35 <unknown>
#3 0x55c2d6515f27 <unknown>
#4 0x55c2d65172d9 <unknown>
#5 0x55c2d651629e <unknown>
#6 0x55c2d65153d2 <unknown>
#7 0x55c2d6515225 <unknown>
#8 0x55c2d6513dc6 <unknown>
#9 0x55c2d6514244 <unknown>
#10 0x55c2d652ce88 <unknown>
#11 0x55c2d659fb05 <unknown>
#12 0x55c2d6587b32 <unknown>
#13 0x55c2d659f47c <unknown>
#14 0x55c2d6587903 <unknown>
#15 0x55c2d655aece <unknown>
#16 0x55c2d655bfde <unknown>
#17 0x55c2d67bc63e <unknown>
#18 0x55c2d67bfb79 <unknown>
#19 0x55c2d67a289e <unknown>
#20 0x55c2d67c0a83 <unknown>
#21 0x55c2d6795505 <unknown>
#22 0x55c2d67e1ca8 <unknown>
#23 0x55c2d67e1e36 <unknown>
#24 0x55c2d67fd333 <unknown>
#25 0x7fb4c82cf609 start_thread
; 709)
[2023-01-06T11:22:00.334+0530] {local_task_job.py:159} INFO - Task exited with return code 1
[2023-01-06T11:22:00.371+0530] {taskinstance.py:2582} INFO - 0 downstream tasks scheduled from follow-on schedule check
