[2023-02-03T02:45:12.905+0530] {taskinstance.py:1087} INFO - Dependencies all met for <TaskInstance: Monthly.load2 scheduled__2023-01-30T00:00:00+00:00 [queued]>
[2023-02-03T02:45:12.917+0530] {taskinstance.py:1087} INFO - Dependencies all met for <TaskInstance: Monthly.load2 scheduled__2023-01-30T00:00:00+00:00 [queued]>
[2023-02-03T02:45:12.917+0530] {taskinstance.py:1283} INFO - 
--------------------------------------------------------------------------------
[2023-02-03T02:45:12.918+0530] {taskinstance.py:1284} INFO - Starting attempt 1 of 4
[2023-02-03T02:45:12.918+0530] {taskinstance.py:1285} INFO - 
--------------------------------------------------------------------------------
[2023-02-03T02:45:12.932+0530] {taskinstance.py:1304} INFO - Executing <Task(PythonOperator): load2> on 2023-01-30 00:00:00+00:00
[2023-02-03T02:45:12.937+0530] {standard_task_runner.py:55} INFO - Started process 10430 to run task
[2023-02-03T02:45:12.940+0530] {standard_task_runner.py:82} INFO - Running: ['airflow', 'tasks', 'run', 'Monthly', 'load2', 'scheduled__2023-01-30T00:00:00+00:00', '--job-id', '3790', '--raw', '--subdir', 'DAGS_FOLDER/Monthly.py', '--cfg-path', '/tmp/tmplv4on7nw']
[2023-02-03T02:45:12.941+0530] {standard_task_runner.py:83} INFO - Job 3790: Subtask load2
[2023-02-03T02:45:12.990+0530] {task_command.py:389} INFO - Running <TaskInstance: Monthly.load2 scheduled__2023-01-30T00:00:00+00:00 [running]> on host DESKTOP-SQIOQPD.
[2023-02-03T02:45:13.063+0530] {taskinstance.py:1511} INFO - Exporting the following env vars:
AIRFLOW_CTX_DAG_EMAIL=nikheleshbhattacharyya@gmail.com
AIRFLOW_CTX_DAG_OWNER=airflow
AIRFLOW_CTX_DAG_ID=Monthly
AIRFLOW_CTX_TASK_ID=load2
AIRFLOW_CTX_EXECUTION_DATE=2023-01-30T00:00:00+00:00
AIRFLOW_CTX_TRY_NUMBER=1
AIRFLOW_CTX_DAG_RUN_ID=scheduled__2023-01-30T00:00:00+00:00
[2023-02-03T02:45:13.071+0530] {taskinstance.py:1772} ERROR - Task failed with exception
Traceback (most recent call last):
  File "/usr/local/lib/python3.8/dist-packages/airflow/operators/python.py", line 175, in execute
    return_value = self.execute_callable()
  File "/usr/local/lib/python3.8/dist-packages/airflow/operators/python.py", line 192, in execute_callable
    return self.python_callable(*self.op_args, **self.op_kwargs)
  File "/root/airflow/dags/Monthly.py", line 537, in load2
    urls = list(context['ti'].xcom_pull(task_ids='extract2'))
TypeError: 'NoneType' object is not iterable
[2023-02-03T02:45:13.075+0530] {taskinstance.py:1322} INFO - Marking task as UP_FOR_RETRY. dag_id=Monthly, task_id=load2, execution_date=20230130T000000, start_date=20230202T211512, end_date=20230202T211513
[2023-02-03T02:45:13.087+0530] {standard_task_runner.py:100} ERROR - Failed to execute job 3790 for task load2 ('NoneType' object is not iterable; 10430)
[2023-02-03T02:45:13.113+0530] {local_task_job.py:159} INFO - Task exited with return code 1
[2023-02-03T02:45:13.131+0530] {taskinstance.py:2582} INFO - 0 downstream tasks scheduled from follow-on schedule check
