[2023-03-17T02:29:50.926+0530] {taskinstance.py:1087} INFO - Dependencies all met for <TaskInstance: FX__Turnover.extract scheduled__2023-02-26T00:00:00+00:00 [queued]>
[2023-03-17T02:29:50.936+0530] {taskinstance.py:1087} INFO - Dependencies all met for <TaskInstance: FX__Turnover.extract scheduled__2023-02-26T00:00:00+00:00 [queued]>
[2023-03-17T02:29:50.936+0530] {taskinstance.py:1283} INFO - 
--------------------------------------------------------------------------------
[2023-03-17T02:29:50.936+0530] {taskinstance.py:1284} INFO - Starting attempt 2 of 4
[2023-03-17T02:29:50.936+0530] {taskinstance.py:1285} INFO - 
--------------------------------------------------------------------------------
[2023-03-17T02:29:50.955+0530] {taskinstance.py:1304} INFO - Executing <Task(PythonOperator): extract> on 2023-02-26 00:00:00+00:00
[2023-03-17T02:29:50.962+0530] {standard_task_runner.py:55} INFO - Started process 2239 to run task
[2023-03-17T02:29:50.977+0530] {standard_task_runner.py:82} INFO - Running: ['airflow', 'tasks', 'run', 'FX__Turnover', 'extract', 'scheduled__2023-02-26T00:00:00+00:00', '--job-id', '4808', '--raw', '--subdir', 'DAGS_FOLDER/FX_turnover.py', '--cfg-path', '/tmp/tmp4cn133k3']
[2023-03-17T02:29:50.983+0530] {standard_task_runner.py:83} INFO - Job 4808: Subtask extract
[2023-03-17T02:29:51.122+0530] {task_command.py:389} INFO - Running <TaskInstance: FX__Turnover.extract scheduled__2023-02-26T00:00:00+00:00 [running]> on host DESKTOP-SQIOQPD.
[2023-03-17T02:29:51.315+0530] {taskinstance.py:1511} INFO - Exporting the following env vars:
AIRFLOW_CTX_DAG_EMAIL=nikheleshbhattacharyya@gmail.com
AIRFLOW_CTX_DAG_OWNER=airflow
AIRFLOW_CTX_DAG_ID=FX__Turnover
AIRFLOW_CTX_TASK_ID=extract
AIRFLOW_CTX_EXECUTION_DATE=2023-02-26T00:00:00+00:00
AIRFLOW_CTX_TRY_NUMBER=2
AIRFLOW_CTX_DAG_RUN_ID=scheduled__2023-02-26T00:00:00+00:00
[2023-03-17T02:30:25.191+0530] {taskinstance.py:1772} ERROR - Task failed with exception
Traceback (most recent call last):
  File "/usr/local/lib/python3.8/dist-packages/airflow/operators/python.py", line 175, in execute
    return_value = self.execute_callable()
  File "/usr/local/lib/python3.8/dist-packages/airflow/operators/python.py", line 192, in execute_callable
    return self.python_callable(*self.op_args, **self.op_kwargs)
  File "/root/airflow/dags/FX_turnover.py", line 141, in extract_fxturn
    python_button1[0].click()
IndexError: list index out of range
[2023-03-17T02:30:25.208+0530] {taskinstance.py:1322} INFO - Marking task as UP_FOR_RETRY. dag_id=FX__Turnover, task_id=extract, execution_date=20230226T000000, start_date=20230316T205950, end_date=20230316T210025
[2023-03-17T02:30:25.229+0530] {standard_task_runner.py:100} ERROR - Failed to execute job 4808 for task extract (list index out of range; 2239)
[2023-03-17T02:30:25.265+0530] {local_task_job.py:159} INFO - Task exited with return code 1
[2023-03-17T02:30:25.286+0530] {taskinstance.py:2582} INFO - 0 downstream tasks scheduled from follow-on schedule check
