[2023-03-17T01:54:14.353+0530] {taskinstance.py:1087} INFO - Dependencies all met for <TaskInstance: FX__Turnover.extract scheduled__2023-02-26T00:00:00+00:00 [queued]>
[2023-03-17T01:54:14.365+0530] {taskinstance.py:1087} INFO - Dependencies all met for <TaskInstance: FX__Turnover.extract scheduled__2023-02-26T00:00:00+00:00 [queued]>
[2023-03-17T01:54:14.365+0530] {taskinstance.py:1283} INFO - 
--------------------------------------------------------------------------------
[2023-03-17T01:54:14.365+0530] {taskinstance.py:1284} INFO - Starting attempt 1 of 4
[2023-03-17T01:54:14.365+0530] {taskinstance.py:1285} INFO - 
--------------------------------------------------------------------------------
[2023-03-17T01:54:14.388+0530] {taskinstance.py:1304} INFO - Executing <Task(PythonOperator): extract> on 2023-02-26 00:00:00+00:00
[2023-03-17T01:54:14.399+0530] {standard_task_runner.py:55} INFO - Started process 1674 to run task
[2023-03-17T01:54:14.399+0530] {standard_task_runner.py:82} INFO - Running: ['airflow', 'tasks', 'run', 'FX__Turnover', 'extract', 'scheduled__2023-02-26T00:00:00+00:00', '--job-id', '4787', '--raw', '--subdir', 'DAGS_FOLDER/FX_turnover.py', '--cfg-path', '/tmp/tmpzi_d0cni']
[2023-03-17T01:54:14.401+0530] {standard_task_runner.py:83} INFO - Job 4787: Subtask extract
[2023-03-17T01:54:14.588+0530] {task_command.py:389} INFO - Running <TaskInstance: FX__Turnover.extract scheduled__2023-02-26T00:00:00+00:00 [running]> on host DESKTOP-SQIOQPD.
[2023-03-17T01:54:14.789+0530] {taskinstance.py:1511} INFO - Exporting the following env vars:
AIRFLOW_CTX_DAG_EMAIL=nikheleshbhattacharyya@gmail.com
AIRFLOW_CTX_DAG_OWNER=airflow
AIRFLOW_CTX_DAG_ID=FX__Turnover
AIRFLOW_CTX_TASK_ID=extract
AIRFLOW_CTX_EXECUTION_DATE=2023-02-26T00:00:00+00:00
AIRFLOW_CTX_TRY_NUMBER=1
AIRFLOW_CTX_DAG_RUN_ID=scheduled__2023-02-26T00:00:00+00:00
[2023-03-17T01:54:15.326+0530] {taskinstance.py:1772} ERROR - Task failed with exception
Traceback (most recent call last):
  File "/usr/local/lib/python3.8/dist-packages/airflow/operators/python.py", line 175, in execute
    return_value = self.execute_callable()
  File "/usr/local/lib/python3.8/dist-packages/airflow/operators/python.py", line 192, in execute_callable
    return self.python_callable(*self.op_args, **self.op_kwargs)
  File "/root/airflow/dags/FX_turnover.py", line 137, in extract_fxturn
    driver = webdriver.Chrome('/usr/local/bin/chromedriver',options=chrome_options)
  File "/usr/local/lib/python3.8/dist-packages/selenium/webdriver/chrome/webdriver.py", line 80, in __init__
    super().__init__(
  File "/usr/local/lib/python3.8/dist-packages/selenium/webdriver/chromium/webdriver.py", line 101, in __init__
    self.service.start()
  File "/usr/local/lib/python3.8/dist-packages/selenium/webdriver/common/service.py", line 104, in start
    self.assert_process_still_running()
  File "/usr/local/lib/python3.8/dist-packages/selenium/webdriver/common/service.py", line 117, in assert_process_still_running
    raise WebDriverException(f"Service {self.path} unexpectedly exited. Status code was: {return_code}")
selenium.common.exceptions.WebDriverException: Message: Service /usr/local/bin/chromedriver unexpectedly exited. Status code was: 1

[2023-03-17T01:54:15.335+0530] {taskinstance.py:1322} INFO - Marking task as UP_FOR_RETRY. dag_id=FX__Turnover, task_id=extract, execution_date=20230226T000000, start_date=20230316T202414, end_date=20230316T202415
[2023-03-17T01:54:15.351+0530] {standard_task_runner.py:100} ERROR - Failed to execute job 4787 for task extract (Message: Service /usr/local/bin/chromedriver unexpectedly exited. Status code was: 1
; 1674)
[2023-03-17T01:54:15.384+0530] {local_task_job.py:159} INFO - Task exited with return code 1
[2023-03-17T01:54:15.410+0530] {taskinstance.py:2582} INFO - 0 downstream tasks scheduled from follow-on schedule check
